Workbook

Sheet AMUSE JAPAN_上期_7-12月
A1: ① AMUSE JAPAN 月間収支まとめ 上期_7-12月
A2: 日 | B2: 項目 | C2: R7.7月 | D2: R7.8月 | E2: R7.9月 | F2: R7.10月 | G2: R7.11月 | H2: R7.12月 | I2: 累 計
A3: 【 支 出 】
B4: ▶ タバコ | C4: =SUM(C5:C8) | D4: =SUM(D5:D8) | E4: =SUM(E5:E8) | F4: =SUM(F5:F8) | G4: =SUM(G5:G8) | H4: =SUM(H5:H8) | I4: =SUM(I5:I8)
A5: 10 | B5: 高田繊維 | C5: 38164 | D5: 263012 | E5: 163936 | F5: 76516 | G5: 164688 | H5: 50572 | I5: =SUM(C5:H5)
A6: 20 | B6: 高田繊維 | C6: 187436 | D6: 61100 | E6: 160176 | F6: 137616 | G6: 87796 | H6: 76892 | I6: =SUM(C6:H6)
A7: 30 | B7: 高田繊維 | C7: 137616 | D7: 180856 | E7: 203792 | F7: 165064 | G7: 258500 | H7: 115808 | I7: =SUM(C7:H7)
B9: ▶ 給与系 | C9: =SUM(C10:C15) | D9: =SUM(D10:D15) | E9: =SUM(E10:E15) | F9: =SUM(F10:F15) | G9: =SUM(G10:G15) | H9: =SUM(H10:H15) | I9: =SUM(I10:I15)
A10: 14 | B10: 給料（総支給） | C10: 3162960 | D10: 3178302 | E10: 3228927 | F10: 3069490 | G10: 3275463 | H10: 3342578 | I10: =SUM(C10:H10)
A11: 31 | B11: 厚生年金 会社負担 | C11: 326990 | D11: 327036 | E11: 327411 | F11: 332834 | G11: 333376 | H11: 332855 | I11: =SUM(C11:H11)
A12: 6 | B12: 労働保険（9月11月2月） | E12: 251514 | G12: 221752 | I12: =SUM(C12:H12)
B13: 社長へ返済 | G13: 500000 | I13: =SUM(C13:H13)
B14: 後払い給与 | I14: =SUM(C14:H14)
B16: ▶ 電気・ガス・水道 | C16: =SUM(C17:C22) | D16: =SUM(D17:D22) | E16: =SUM(E17:E22) | F16: =SUM(F17:F22) | G16: =SUM(G17:G22) | H16: =SUM(H17:H22) | I16: =SUM(I17:I22)
A17: 14 | B17: 電気料金 | C17: 1105416 | D17: 1196167 | E17: 1193304 | F17: 1082285 | G17: 939467 | H17: 877899 | I17: =SUM(C17:H17)
B18: 駐車場 電気 | C18: 5605 | D18: 5854 | E18: 5657 | F18: 6603 | G18: 7145 | H18: 6887 | I18: =SUM(C18:H18)
B19: 駐車場 電気 | C19: 2445 | D19: 2157 | E19: 2073 | F19: 2095 | G19: 2322 | H19: 2314 | I19: =SUM(C19:H19)
B20: 東邦液化ｶﾞｽ 食堂 | C20: 1507 | D20: 1892 | E20: 1262 | F20: 1200 | G20: 1500 | H20: 1500 | I20: =SUM(C20:H20)
A21: 31 | B21: 水道料(羽島）偶数月 | H21: 1892 | I21: =SUM(C21:H21)
B23: ▶ 雑費 | C23: =SUM(C24:C48) | D23: =SUM(D24:D48) | E23: =SUM(E24:E48) | F23: =SUM(F24:F48) | G23: =SUM(G24:G48) | H23: =SUM(H24:H48) | I23: =SUM(I24:I48)
A24: 17 | B24: 日浦新聞店 | C24: 7400 | D24: 7400 | E24: 7400 | F24: 7400 | G24: 7400 | H24: 7400 | I24: =SUM(C24:H24)
A25: 10 | B25: ネットバンキング | C25: 3340 | D25: 3340 | E25: 3340 | F25: 3340 | G25: 3340 | H25: 3340 | I25: =SUM(C25:H25)
A26: 10 | B26: 振込手数料 | C26: 36960 | D26: 18590 | E26: 9735 | F26: 33660 | G26: 19690 | H26: 9075 | I26: =SUM(C26:H26)
A27: 20 | B27: 大日へ立替分清算 前月分 | C27: 8646 | D27: 3150 | E27: 3819 | F27: 19648 | G27: 1694 | H27: 34018 | I27: =SUM(C27:H27)
B28: 山田組 廃棄物 | C28: 19360 | D28: 19360 | E28: 19360 | F28: 19360 | G28: 19360 | H28: 19360 | I28: =SUM(C28:H28)
A29: 8 | B29: 小口現金 本社 | E29: 100000 | F29: 50000 | G29: 200000 | H29: 150000 | I29: =SUM(C29:H29)
A30: 4 | B30: 小口現金 | C30: 100000 | D30: 100000 | I30: =SUM(C30:H30)
B31: 小口現金 店舗 | G31: 110000 | I31: =SUM(C31:H31)
A32: 20 | B32: ネットプロテクションズ | E32: 10340 | F32: 16500 | H32: 11220 | I32: =SUM(C32:H32)
A33: 13 | B33: でんさい手数料 | G33: 5940 | H33: 46860 | I33: =SUM(C33:H33)
B34: ヤマト | C34: 660 | I34: =SUM(C34:H34)
A35: 26 | B35: 佐川急便 | H35: 909 | I35: =SUM(C35:H35)
B36: 理念と経営 | D36: 11500 | I36: =SUM(C36:H36)
B37: IN HOME エアコン修理 | D37: 29700 | I37: =SUM(C37:H37)
B38: JQA定期審査 | F38: 251240 | I38: =SUM(C38:H38)
A39: 20 | B39: エムテック | G39: 66000 | I39: =SUM(C39:H39)
B40: トバナ産業 | G40: 158400 | I40: =SUM(C40:H40)
B41: 浄化槽 | G41: 10000 | I41: =SUM(C41:H41)
B42: 十六大日 立替 | G42: 118140 | I42: =SUM(C42:H42)
A43: 10 | B43: 覚建築 | H43: 108900 | I43: =SUM(C43:H43)
...

Sheet AMUSE JAPAN_下期_1-6月
A1: ① AMUSE JAPAN 月間収支まとめ 下期_1-6月
A2: 日 | B2: 項目 | C2: R8.1月 | D2: R8.2月 | E2: R8.3月 | F2: R8.4月 | G2: R8.5月 | H2: R8.6月 | I2: 下期累計 | J2: 上期累計 | K2: 通期合計
A3: 【 支 出 】
B4: ▶ タバコ | C4: =SUM(C5:C8) | D4: =SUM(D5:D8) | E4: =SUM(E5:E8) | F4: =SUM(F5:F8) | G4: =SUM(G5:G8) | H4: =SUM(H5:H8) | I4: =SUM(I5:I8) | J4: =SUM(J5:J8) | K4: =SUM(K5:K8)
A5: 10 | B5: 高田繊維 | C5: 351560 | D5: 147956 | E5: 109604 | F5: 432400 | I5: =SUM(C5:H5) | J5: ='AMUSE JAPAN_上期_7-12月'!I5 | K5: =I5+J5
A6: 20 | B6: 高田繊維 | C6: 27260 | D6: 98512 | E6: 54896 | F6: 142316 | I6: =SUM(C6:H6) | J6: ='AMUSE JAPAN_上期_7-12月'!I6 | K6: =I6+J6
A7: 30 | B7: 高田繊維 | C7: 77832 | D7: 203604 | E7: 187060 | I7: =SUM(C7:H7) | J7: ='AMUSE JAPAN_上期_7-12月'!I7 | K7: =I7+J7
B9: ▶ 給与系 | C9: =SUM(C10:C14) | D9: =SUM(D10:D14) | E9: =SUM(E10:E14) | F9: =SUM(F10:F14) | G9: =SUM(G10:G14) | H9: =SUM(H10:H14) | I9: =SUM(I10:I14) | J9: =SUM(J10:J14) | K9: =SUM(K10:K14)
A10: 14 | B10: 給料（総支給） | C10: 3585800 | D10: 3223676 | E10: 3214319 | F10: 3262174 | I10: =SUM(C10:H10) | J10: ='AMUSE JAPAN_上期_7-12月'!I10 | K10: =I10+J10
A11: 31 | B11: 厚生年金 会社負担 | C11: 333326 | D11: 333741 | E11: 332993 | F11: 332051 | I11: =SUM(C11:H11) | J11: ='AMUSE JAPAN_上期_7-12月'!I11 | K11: =I11+J11
A12: 6 | B12: 労働保険（9月11月2月） | D12: 221752 | I12: =SUM(C12:H12) | J12: ='AMUSE JAPAN_上期_7-12月'!I12 | K12: =I12+J12
B13: 後払い給与 | I13: =SUM(C13:H13) | J13: ='AMUSE JAPAN_上期_7-12月'!I14 | K13: =I13+J13
B15: ▶ 電気・ガス・水道 | C15: =SUM(C16:C21) | D15: =SUM(D16:D21) | E15: =SUM(E16:E21) | F15: =SUM(F16:F21) | G15: =SUM(G16:G21) | H15: =SUM(H16:H21) | I15: =SUM(I16:I21) | J15: =SUM(J16:J21) | K15: =SUM(K16:K21)
B16: 東邦液化ｶﾞｽ 食堂 | C16: 1500 | D16: 1500 | E16: 1500 | F16: 1500 | G16: 1500 | I16: =SUM(C16:H16) | J16: ='AMUSE JAPAN_上期_7-12月'!I20 | K16: =I16+J16
B17: 電気料金 | C17: 1038683 | D17: 1036025 | E17: 847675 | F17: 862474 | I17: =SUM(C17:H17) | J17: ='AMUSE JAPAN_上期_7-12月'!I17 | K17: =I17+J17
B18: 駐車場 電気 | C18: 8183 | D18: 5793 | E18: 5407 | I18: =SUM(C18:H18) | J18: ='AMUSE JAPAN_上期_7-12月'!I18 | K18: =I18+J18
B19: 駐車場 電気 | C19: 2306 | D19: 1779 | E19: 1801 | I19: =SUM(C19:H19) | J19: ='AMUSE JAPAN_上期_7-12月'!I19 | K19: =I19+J19
A20: 31 | B20: 水道料(羽島）偶数月 | I20: =SUM(C20:H20) | J20: ='AMUSE JAPAN_上期_7-12月'!I21 | K20: =I20+J20
B22: ▶ 雑費 | C22: =SUM(C23:C44) | D22: =SUM(D23:D44) | E22: =SUM(E23:E44) | F22: =SUM(F23:F44) | G22: =SUM(G23:G44) | H22: =SUM(H23:H44) | I22: =SUM(I23:I44) | J22: =SUM(J23:J44) | K22: =SUM(K23:K44)
A23: 17 | B23: 日浦新聞店 | C23: 7400 | D23: 7400 | E23: 7400 | F23: 7400 | G23: 7400 | I23: =SUM(C23:H23) | J23: ='AMUSE JAPAN_上期_7-12月'!I24 | K23: =I23+J23
A24: 10 | B24: ネットバンキング | C24: 3340 | D24: 3340 | E24: 3340 | F24: 3340 | G24: 3340 | I24: =SUM(C24:H24) | J24: ='AMUSE JAPAN_上期_7-12月'!I25 | K24: =I24+J24
B25: 山田組 廃棄物 | C25: 19360 | D25: 19360 | E25: 19360 | F25: 19360 | G25: 19360 | I25: =SUM(C25:H25) | J25: ='AMUSE JAPAN_上期_7-12月'!I28 | K25: =I25+J25
A26: 10 | B26: 振込手数料 | C26: 37345 | D26: 10780 | E26: 23100 | F26: 34760 | I26: =SUM(C26:H26) | J26: ='AMUSE JAPAN_上期_7-12月'!I26 | K26: =I26+J26
B27: でんさい手数料 | C27: 5280 | D27: 23760 | E27: 15840 | I27: =SUM(C27:H27) | J27: ='AMUSE JAPAN_上期_7-12月'!I33 | K27: =I27+J27
A28: 20 | B28: 大日へ立替分清算 前月分 | C28: 12357 | D28: 97610 | E28: 8858 | I28: =SUM(C28:H28) | J28: ='AMUSE JAPAN_上期_7-12月'!I27 | K28: =I28+J28
A29: 21 | B29: 小口現金 本社 | C29: 150000 | E29: 100000 | I29: =SUM(C29:H29) | J29: ='AMUSE JAPAN_上期_7-12月'!I29 | K29: =I29+J29
A30: 3 | B30: 小口現金 | D30: 130000 | E30: 60000 | I30: =SUM(C30:H30) | J30: ='AMUSE JAPAN_上期_7-12月'!I30 | K30: =I30+J30
A31: 20 | B31: 小口現金 | D31: 150000 | I31: =SUM(C31:H31) | K31: =I31+J31
A32: 26 | B32: 佐川急便 | C32: 2439 | I32: =SUM(C32:H32) | J32: ='AMUSE JAPAN_上期_7-12月'!I35 | K32: =I32+J32
A33: 10 | B33: オノデン | C33: 250000 | I33: =SUM(C33:H33) | K33: =I33+J33
A34: 30 | B34: 覚建築 | C34: 154000 | I34: =SUM(C34:H34) | J34: ='AMUSE JAPAN_上期_7-12月'!I43 | K34: =I34+J34
B35: ネスコ | C35: 1076196 | I35: =SUM(C35:H35) | K35: =I35+J35
B36: ネットプロテクションズ | D36: 4411 | I36: =SUM(C36:H36) | J36: ='AMUSE JAPAN_上期_7-12月'!I32 | K36: =I36+J36
B37: ネットプロテクションズ | D37: 13530 | I37: =SUM(C37:H37) | K37: =I37+J37
B38: エムテック | F38: 44000 | I38: =SUM(C38:H38) | J38: ='AMUSE JAPAN_上期_7-12月'!I39 | K38: =I38+J38
B39: P-POP年払い | F39: 99000 | I39: =SUM(C39:H39) | K39: =I39+J39
B40: 健康診断 | F40: 59400 | I40: =SUM(C40:H40) | K40: =I40+J40
B41: ヤマト | I41: =SUM(C41:H41) | J41: ='AMUSE JAPAN_上期_7-12月'!I34 | K41: =I41+J41
B42: 雑費 | I42: =SUM(C42:H42) | J42: ='AMUSE JAPAN_上期_7-12月'!I46 | K42: =I42+J42
B43: 店研創意 | I43: =SUM(C43:H43) | J43: ='AMUSE JAPAN_上期_7-12月'!I47 | K43: =I43+J43
...

Sheet ウェルピア羽島_上期_7-12月
A1: ② ウェルピア羽島 月間収支まとめ 上期_7-12月
A2: 日 | B2: 項目 | C2: R7.7月 | D2: R7.8月 | E2: R7.9月 | F2: R7.10月 | G2: R7.11月 | H2: R7.12月 | I2: 累 計
A3: 【 支 出 】
B4: ▶ 給与 福利 | C4: =SUM(C5:C14) | D4: =SUM(D5:D14) | E4: =SUM(E5:E14) | F4: =SUM(F5:F14) | G4: =SUM(G5:G14) | H4: =SUM(H5:H14) | I4: =SUM(I5:I14)
A5: 20 | B5: 給与 | C5: 5376728 | D5: 5644326 | E5: 5342290 | F5: 5234857 | G5: 5574689 | H5: 5591647 | I5: =SUM(C5:H5)
B6: 役員報酬 | C6: 1838257 | D6: 1838257 | E6: 1838257 | F6: 1838257 | G6: 1838257 | H6: 2427003 | I6: =SUM(C6:H6)
A7: 31 | B7: 社員社保料（会社負担分） | C7: 247925 | D7: 249450 | E7: 253738 | F7: 261255 | G7: 262357 | H7: 262879 | I7: =SUM(C7:H7)
B8: 役員社保料（会社負担分） | C8: 190483 | D8: 190483 | E8: 194514 | F8: 194514 | G8: 194514 | H8: 439197 | I8: =SUM(C8:H8)
B9: 大日出向費 事務費10万 | C9: 193323 | D9: 197767 | E9: 184554 | F9: 232835 | G9: 408247 | H9: 385658 | I9: =SUM(C9:H9)
B10: 寿食品 出前弁当（給与から控除） | C10: 33534 | D10: 36018 | E10: 38502 | F10: 37881 | G10: 40365 | H10: 37260 | I10: =SUM(C10:H10)
A11: 10 | B11: IP ラウンジ使用料 | C11: 52800 | D11: 52800 | F11: 52800 | G11: 52800 | H11: 52800 | I11: =SUM(C11:H11)
B12: 労働保険料（9.11.2.） | E12: 574090 | G12: 385713 | I12: =SUM(C12:H12)
A13: 30 | B13: 業務改善手当 | E13: 2931910 | I13: =SUM(C13:H13)
B15: ▶ 地代家賃/固定資産 | C15: =SUM(C16:C21) | D15: =SUM(D16:D21) | E15: =SUM(E16:E21) | F15: =SUM(F16:F21) | G15: =SUM(G16:G21) | H15: =SUM(H16:H21) | I15: =SUM(I16:I21)
A16: 末 | B16: 大日産業へ 家賃（駐車場含む） | C16: 360000 | D16: 360000 | E16: 360000 | F16: 360000 | G16: 360000 | H16: 360000 | I16: =SUM(C16:H16)
A17: 末 | B17: 47街区２F 貸事務所 | C17: 660000 | D17: 660000 | E17: 660000 | F17: 660000 | G17: 660000 | H17: 660000 | I17: =SUM(C17:H17)
B18: 固定資産税/自動車税/消費税 | G18: 1109900 | I18: =SUM(C18:H18)
B19: 固定資産税/自動車税（年1回） | H19: 834500 | I19: =SUM(C19:H19)
B20: 正木太陽光 尾関15万 毎年3月 | I20: =SUM(C20:H20)
B22: ▶ 顧問料 支払手数料 | C22: =SUM(C23:C29) | D22: =SUM(D23:D29) | E22: =SUM(E23:E29) | F22: =SUM(F23:F29) | G22: =SUM(G23:G29) | H22: =SUM(H23:H29) | I22: =SUM(I23:I29)
B23: 荒川会計 | C23: 110000 | D23: 110000 | E23: 110000 | F23: 110000 | G23: 110000 | H23: 110000 | I23: =SUM(C23:H23)
A24: 28 | B24: ブリックス 税務 | C24: 12500 | D24: 12500 | F24: 12500 | G24: 12500 | H24: 12500 | I24: =SUM(C24:H24)
B25: ブリックス給与計算 | C25: 8750 | D25: 8750 | F25: 8750 | G25: 8750 | H25: 8750 | I25: =SUM(C25:H25)
A26: 28 | B26: ブリックス 税務労務 | E26: 21250 | I26: =SUM(C26:H26)
B27: 行政書士沼田 | D27: 10000 | E27: 106800 | F27: 10000 | G27: 10000 | H27: 10000 | I27: =SUM(C27:H27)
A28: 末 | B28: Toリサーチ 顧問料 | C28: 500000 | I28: =SUM(C28:H28)
B30: ▶ 水道光熱費 | C30: =SUM(C31:C32) | D30: =SUM(D31:D32) | E30: =SUM(E31:E32) | F30: =SUM(F31:F32) | G30: =SUM(G31:G32) | H30: =SUM(H31:H32) | I30: =SUM(I31:I32)
A31: 20 | B31: 大日産業へ 電気代 | C31: 8030 | D31: 15216 | E31: 10548 | F31: 14717 | H31: 15241 | I31: =SUM(C31:H31)
B33: ▶ 保険料 | C33: =SUM(C34:C38) | D33: =SUM(D34:D38) | E33: =SUM(E34:E38) | F33: =SUM(F34:F38) | G33: =SUM(G34:G38) | H33: =SUM(H34:H38) | I33: =SUM(I34:I38)
B34: 日本生命 社長奥様 | C34: 27517 | D34: 27517 | E34: 27517 | F34: 27517 | G34: 27517 | H34: 27517 | I34: =SUM(C34:H34)
A35: 26 | B35: ぎしん 保険 | C35: 50000 | D35: 50000 | E35: 50000 | F35: 50000 | G35: 50000 | H35: 50000 | I35: =SUM(C35:H35)
B36: アルファード 保険 | C36: 20030 | D36: 20030 | E36: 20030 | F36: 20030 | G36: 20030 | H36: 20030 | I36: =SUM(C36:H36)
B37: 谷汲太陽光 （年一回）389080 | D37: 389080 | I37: =SUM(C37:H37)
B39: ▶ リース料 | C39: =SUM(C40:C44) | D39: =SUM(D40:D44) | E39: =SUM(E40:E44) | F39: =SUM(F40:F44) | G39: =SUM(G40:G44) | H39: =SUM(H40:H44) | I39: =SUM(I40:I44)
B40: しんきんコピー機リース | C40: 13860 | D40: 13860 | E40: 13860 | F40: 13860 | G40: 13860 | H40: 13860 | I40: =SUM(C40:H40)
B41: しんきん什器 B47二階 | C41: 137720 | D41: 137720 | E41: 137720 | F41: 137720 | G41: 137720 | I41: =SUM(C41:H41)
B42: しんきん什器 B47二階 R8.3月迄 | H42: 137720 | I42: =SUM(C42:H42)
A43: 10 | B43: IP ラウンジ使用料 | E43: 52800 | I43: =SUM(C43:H43)
B45: ▶ 通信費 | C45: =SUM(C46:C48) | D45: =SUM(D46:D48) | E45: =SUM(E46:E48) | F45: =SUM(F46:F48) | G45: =SUM(G46:G48) | H45: =SUM(H46:H48) | I45: =SUM(I46:I48)
A46: 末 | B46: ゴラック カウンター | C46: 6695 | D46: 6662 | E46: 8985 | F46: 11408 | G46: 4403 | H46: 4733 | I46: =SUM(C46:H46)
...

Sheet ウェルピア羽島_下期_1-6月
A1: ② ウェルピア羽島 月間収支まとめ 下期_1-6月
A2: 日 | B2: 項目 | C2: R8.1月 | D2: R8.2月 | E2: R8.3月 | F2: R8.4月 | G2: R8.5月 | H2: R8.6月 | I2: 下期累計 | J2: 上期累計 | K2: 通期合計
A3: 【 支 出 】
B4: ▶ 給与 福利 | C4: =SUM(C5:C13) | D4: =SUM(D5:D13) | E4: =SUM(E5:E13) | F4: =SUM(F5:F13) | G4: =SUM(G5:G13) | H4: =SUM(H5:H13) | I4: =SUM(I5:I13) | J4: =SUM(J5:J13) | K4: =SUM(K5:K13)
A5: 10 | B5: IP ラウンジ使用料 | C5: 52800 | D5: 52800 | E5: 52800 | F5: 52800 | G5: 52800 | I5: =SUM(C5:H5) | J5: ='ウェルピア羽島_上期_7-12月'!I11 | K5: =I5+J5
A6: 20 | B6: 給与 | C6: 5786776 | D6: 5733757 | E6: 5336065 | F6: 5965710 | I6: =SUM(C6:H6) | J6: ='ウェルピア羽島_上期_7-12月'!I5 | K6: =I6+J6
B7: 役員報酬 | C7: 2427003 | D7: 2427003 | E7: 2423503 | F7: 2423503 | I7: =SUM(C7:H7) | J7: ='ウェルピア羽島_上期_7-12月'!I6 | K7: =I7+J7
A8: 31 | B8: 社員社保料（会社負担分） | C8: 264064 | D8: 263789 | E8: 269776 | F8: 272310 | I8: =SUM(C8:H8) | J8: ='ウェルピア羽島_上期_7-12月'!I7 | K8: =I8+J8
B9: 役員社保料（会社負担分） | C9: 285701 | D9: 285701 | E9: 285701 | F9: 147297 | I9: =SUM(C9:H9) | J9: ='ウェルピア羽島_上期_7-12月'!I8 | K9: =I9+J9
B10: 大日出向費 事務費10万 | C10: 303334 | D10: 288682 | E10: 287368 | F10: 301344 | I10: =SUM(C10:H10) | J10: ='ウェルピア羽島_上期_7-12月'!I9 | K10: =I10+J10
B11: 寿食品 出前弁当（給与から控除） | C11: 37260 | E11: 21735 | F11: 22977 | I11: =SUM(C11:H11) | J11: ='ウェルピア羽島_上期_7-12月'!I10 | K11: =I11+J11
B12: 労働保険料（9.11.2.） | D12: 385713 | I12: =SUM(C12:H12) | J12: ='ウェルピア羽島_上期_7-12月'!I12 | K12: =I12+J12
B14: ▶ 地代家賃/固定資産 | C14: =SUM(C15:C19) | D14: =SUM(D15:D19) | E14: =SUM(E15:E19) | F14: =SUM(F15:F19) | G14: =SUM(G15:G19) | H14: =SUM(H15:H19) | I14: =SUM(I15:I19) | J14: =SUM(J15:J19) | K14: =SUM(K15:K19)
A15: 末 | B15: 大日産業へ 家賃（駐車場含む） | C15: 360000 | D15: 360000 | E15: 360000 | F15: 360000 | G15: 360000 | I15: =SUM(C15:H15) | J15: ='ウェルピア羽島_上期_7-12月'!I16 | K15: =I15+J15
A16: 末 | B16: 47街区２F 貸事務所 | C16: 660000 | D16: 660000 | E16: 660000 | F16: 660000 | G16: 660000 | I16: =SUM(C16:H16) | J16: ='ウェルピア羽島_上期_7-12月'!I17 | K16: =I16+J16
B17: 固定資産税/自動車税（年1回） | D17: 172000 | F17: 299200 | I17: =SUM(C17:H17) | J17: ='ウェルピア羽島_上期_7-12月'!I19 | K17: =I17+J17
B18: 正木太陽光 尾関15万 毎年3月 | E18: 150000 | I18: =SUM(C18:H18) | J18: ='ウェルピア羽島_上期_7-12月'!I20 | K18: =I18+J18
B20: ▶ 顧問料 支払手数料 | C20: =SUM(C21:C25) | D20: =SUM(D21:D25) | E20: =SUM(E21:E25) | F20: =SUM(F21:F25) | G20: =SUM(G21:G25) | H20: =SUM(H21:H25) | I20: =SUM(I21:I25) | J20: =SUM(J21:J25) | K20: =SUM(K21:K25)
A21: 28 | B21: ブリックス 税務 | C21: 12500 | D21: 12500 | E21: 12500 | F21: 12500 | G21: 12500 | I21: =SUM(C21:H21) | J21: ='ウェルピア羽島_上期_7-12月'!I24 | K21: =I21+J21
B22: ブリックス給与計算 | C22: 8750 | D22: 8750 | E22: 8750 | F22: 8750 | G22: 8750 | I22: =SUM(C22:H22) | J22: ='ウェルピア羽島_上期_7-12月'!I25 | K22: =I22+J22
B23: 荒川会計 | C23: 110000 | D23: 110000 | E23: 110000 | F23: 110000 | G23: 110000 | I23: =SUM(C23:H23) | J23: ='ウェルピア羽島_上期_7-12月'!I23 | K23: =I23+J23
B24: 行政書士沼田 | C24: 10000 | D24: 10000 | E24: 10000 | F24: 10000 | G24: 10000 | I24: =SUM(C24:H24) | J24: ='ウェルピア羽島_上期_7-12月'!I27 | K24: =I24+J24
B26: ▶ 水道光熱費 | C26: =SUM(C27:C29) | D26: =SUM(D27:D29) | E26: =SUM(E27:E29) | F26: =SUM(F27:F29) | G26: =SUM(G27:G29) | H26: =SUM(H27:H29) | I26: =SUM(I27:I29) | J26: =SUM(J27:J29) | K26: =SUM(K27:K29)
A27: 20 | B27: 大日産業へ 電気代 | C27: 229663 | D27: 96240 | I27: =SUM(C27:H27) | J27: ='ウェルピア羽島_上期_7-12月'!I31 | K27: =I27+J27
A28: 20 | B28: 大日産業へ 電気代など | E28: 79527 | F28: 15937 | I28: =SUM(C28:H28) | K28: =I28+J28
B30: ▶ 保険料 | C30: =SUM(C31:C35) | D30: =SUM(D31:D35) | E30: =SUM(E31:E35) | F30: =SUM(F31:F35) | G30: =SUM(G31:G35) | H30: =SUM(H31:H35) | I30: =SUM(I31:I35) | J30: =SUM(J31:J35) | K30: =SUM(K31:K35)
B31: 日本生命 社長奥様 | C31: 27517 | D31: 27517 | E31: 27517 | F31: 27517 | G31: 27517 | I31: =SUM(C31:H31) | J31: ='ウェルピア羽島_上期_7-12月'!I34 | K31: =I31+J31
A32: 26 | B32: ぎしん 保険 | C32: 50000 | D32: 50000 | E32: 50000 | F32: 50000 | G32: 50000 | I32: =SUM(C32:H32) | J32: ='ウェルピア羽島_上期_7-12月'!I35 | K32: =I32+J32
B33: アルファード 保険 | C33: 20030 | D33: 20030 | E33: 20030 | F33: 20030 | G33: 20030 | I33: =SUM(C33:H33) | J33: ='ウェルピア羽島_上期_7-12月'!I36 | K33: =I33+J33
B34: 谷汲太陽光 （年一回）389080 | I34: =SUM(C34:H34) | J34: ='ウェルピア羽島_上期_7-12月'!I37 | K34: =I34+J34
B36: ▶ リース料 | C36: =SUM(C37:C39) | D36: =SUM(D37:D39) | E36: =SUM(E37:E39) | F36: =SUM(F37:F39) | G36: =SUM(G37:G39) | H36: =SUM(H37:H39) | I36: =SUM(I37:I39) | J36: =SUM(J37:J39) | K36: =SUM(K37:K39)
B37: しんきんコピー機リース | C37: 13860 | D37: 13860 | E37: 13860 | F37: 13860 | G37: 13860 | I37: =SUM(C37:H37) | J37: ='ウェルピア羽島_上期_7-12月'!I40 | K37: =I37+J37
B38: しんきん什器 B47二階 R8.3月迄 | C38: 137720 | D38: 137720 | E38: 137720 | I38: =SUM(C38:H38) | J38: ='ウェルピア羽島_上期_7-12月'!I42 | K38: =I38+J38
B40: ▶ 通信費 | C40: =SUM(C41:C43) | D40: =SUM(D41:D43) | E40: =SUM(E41:E43) | F40: =SUM(F41:F43) | G40: =SUM(G41:G43) | H40: =SUM(H41:H43) | I40: =SUM(I41:I43) | J40: =SUM(J41:J43) | K40: =SUM(K41:K43)
A41: 末 | B41: ゴラック カウンター | C41: 5924 | D41: 5256 | E41: 5746 | F41: 4337 | I41: =SUM(C41:H41) | J41: ='ウェルピア羽島_上期_7-12月'!I46 | K41: =I41+J41
B42: 電話料金 NTT | E42: 8034 | I42: =SUM(C42:H42) | J42: ='ウェルピア羽島_上期_7-12月'!I47 | K42: =I42+J42
B44: ▶ 車両費 | C44: =SUM(C45:C47) | D44: =SUM(D45:D47) | E44: =SUM(E45:E47) | F44: =SUM(F45:F47) | G44: =SUM(G45:G47) | H44: =SUM(H45:H47) | I44: =SUM(I45:I47) | J44: =SUM(J45:J47) | K44: =SUM(K45:K47)
B45: 大日 車６台携帯２台貸与 | C45: 110000 | D45: 110000 | E45: 110000 | F45: 110000 | G45: 110000 | I45: =SUM(C45:H45) | J45: ='ウェルピア羽島_上期_7-12月'!I50 | K45: =I45+J45
B46: アルファード修理 | F46: 103862 | I46: =SUM(C46:H46) | K46: =I46+J46
B48: ▶ 雑費/消耗品 | C48: =SUM(C49:C64) | D48: =SUM(D49:D64) | E48: =SUM(E49:E64) | F48: =SUM(F49:F64) | G48: =SUM(G49:G64) | H48: =SUM(H49:H64) | I48: =SUM(I49:I64) | J48: =SUM(J49:J64) | K48: =SUM(K49:K64)
...

Sheet ウェルピア山県_上期_7-12月
A1: ③ ウェルピア山県 月間収支まとめ 上期_7-12月
A2: 日 | B2: 項目 | C2: R7.7月 | D2: R7.8月 | E2: R7.9月 | F2: R7.10月 | G2: R7.11月 | H2: R7.12月 | I2: 累 計
A3: 【 支 出 】
B4: ▶ 給与 福利 | C4: =SUM(C5:C12) | D4: =SUM(D5:D12) | E4: =SUM(E5:E12) | F4: =SUM(F5:F12) | G4: =SUM(G5:G12) | H4: =SUM(H5:H12) | I4: =SUM(I5:I12)
A5: 20 | B5: 給与 | C5: 603281 | D5: 618143 | E5: 628369 | F5: 593838 | G5: 648177 | H5: 636467 | I5: =SUM(C5:H5)
A6: 31 | B6: 社員社保料（会社負担分） | C6: 66079 | D6: 66162 | E6: 66217 | F6: 66027 | G6: 66327 | H6: 66233 | I6: =SUM(C6:H6)
A7: 20 | B7: 利用者 工賃 業務委託料 | C7: 157325 | D7: 202478 | E7: 193285 | F7: 197161 | G7: 201361 | H7: 205625 | I7: =SUM(C7:H7)
B8: AJ出向費 | C8: 110000 | D8: 110000 | E8: 110000 | F8: 110000 | G8: 110000 | H8: 110000 | I8: =SUM(C8:H8)
B9: 出前弁当 | C9: 63201 | D9: 80308 | E9: 73656 | F9: 74131 | G9: 76507 | H9: 74131 | I9: =SUM(C9:H9)
B10: 労働保険料（9.11.2.） | I10: =SUM(C10:H10)
B11: 増田医院 健康診断 | I11: =SUM(C11:H11)
B13: ▶ 地代家賃/水光熱/固定資産 | C13: =SUM(C14:C15) | D13: =SUM(D14:D15) | E13: =SUM(E14:E15) | F13: =SUM(F14:F15) | G13: =SUM(G14:G15) | H13: =SUM(H14:H15) | I13: =SUM(I14:I15)
A14: 末 | B14: 矢崎商店 家賃・高熱費 | C14: 180000 | D14: 180000 | E14: 180000 | F14: 180000 | G14: 180000 | H14: 180000 | I14: =SUM(C14:H14)
B16: ▶ 顧問料 支払手数料 | C16: =SUM(C17:C20) | D16: =SUM(D17:D20) | E16: =SUM(E17:E20) | F16: =SUM(F17:F20) | G16: =SUM(G17:G20) | H16: =SUM(H17:H20) | I16: =SUM(I17:I20)
A17: 28 | B17: ブリックス 税務 | C17: 12500 | D17: 12500 | E17: 12500 | F17: 12500 | G17: 12500 | H17: 12500 | I17: =SUM(C17:H17)
B18: ブリックス給与計算 | C18: 8750 | D18: 8750 | E18: 8750 | F18: 8750 | G18: 8750 | H18: 8750 | I18: =SUM(C18:H18)
B19: 沼田行政書士 | C19: 10000 | D19: 10000 | E19: 10000 | F19: 10000 | G19: 10000 | H19: 10000 | I19: =SUM(C19:H19)
B21: ▶ リース料 | C21: =SUM(C22:C23) | D21: =SUM(D22:D23) | E21: =SUM(E22:E23) | F21: =SUM(F22:F23) | G21: =SUM(G22:G23) | H21: =SUM(H22:H23) | I21: =SUM(I22:I23)
B22: しんきんリース ｺﾋﾟｰ機 | C22: 13860 | D22: 13860 | E22: 13860 | F22: 13860 | G22: 13860 | H22: 13860 | I22: =SUM(C22:H22)
B24: ▶ 通信費 | C24: =SUM(C25:C27) | D24: =SUM(D25:D27) | E24: =SUM(E25:E27) | F24: =SUM(F25:F27) | G24: =SUM(G25:G27) | H24: =SUM(H25:H27) | I24: =SUM(I25:I27)
A25: 末 | B25: ゴラック カウンター | C25: 1940 | D25: 1123 | E25: 1507 | F25: 1652 | G25: 3195 | H25: 1505 | I25: =SUM(C25:H25)
B26: テレマーカー | C26: 8282 | D26: 7897 | E26: 7738 | F26: 8161 | G26: 7858 | H26: 7861 | I26: =SUM(C26:H26)
B28: ▶ 車両費 | C28: =SUM(C29:C30) | D28: =SUM(D29:D30) | E28: =SUM(E29:E30) | F28: =SUM(F29:F30) | G28: =SUM(G29:G30) | H28: =SUM(H29:H30) | I28: =SUM(I29:I30)
B29: 大日 車６台携帯２台貸与 | C29: 110000 | D29: 110000 | E29: 110000 | F29: 110000 | G29: 110000 | H29: 110000 | I29: =SUM(C29:H29)
B31: ▶ 雑費/消耗品 | C31: =SUM(C32:C39) | D31: =SUM(D32:D39) | E31: =SUM(E32:E39) | F31: =SUM(F32:F39) | G31: =SUM(G32:G39) | H31: =SUM(H32:H39) | I31: =SUM(I32:I39)
B32: BIZバンク 利用料 | C32: 1620 | D32: 1620 | E32: 1620 | F32: 1620 | G32: 1620 | H32: 1620 | I32: =SUM(C32:H32)
B33: リクルート 勤怠管理 | C33: 22000 | D33: 16500 | E33: 16500 | F33: 16500 | G33: 16500 | H33: 16500 | I33: =SUM(C33:H33)
B34: リクルート 募集 | I34: =SUM(C34:H34)
B35: 中島清掃 | C35: 2200 | D35: 2200 | E35: 2200 | F35: 2200 | G35: 2200 | H35: 2200 | I35: =SUM(C35:H35)
B36: 清芳屋 | D36: 4300 | F36: 4796 | G36: 9770 | I36: =SUM(C36:H36)
A37: 10 | B37: 小口現金 | G37: 100000 | I37: =SUM(C37:H37)
B38: モノタロウ | I38: =SUM(C38:H38)
B40: ▶ 銀行返済 | C40: =SUM(C41:C43) | D40: =SUM(D41:D43) | E40: =SUM(E41:E43) | F40: =SUM(F41:F43) | G40: =SUM(G41:G43) | H40: =SUM(H41:H43) | I40: =SUM(I41:I43)
B41: 岐信 500万円（72回〜76回） | C41: 60021 | D41: 60021 | E41: 59861 | F41: 59756 | G41: 59701 | I41: =SUM(C41:H41)
B42: 岐信 500万円 84×77 R8.7迄 | H42: 59621 | I42: =SUM(C42:H42)
B44: ① 支出合計 | C44: =C4+C13+C16+C21+C24+C28+C31+C40 | D44: =D4+D13+D16+D21+D24+D28+D31+D40 | E44: =E4+E13+E16+E21+E24+E28+E31+E40 | F44: =F4+F13+F16+F21+F24+F28+F31+F40 | G44: =G4+G13+G16+G21+G24+G28+G31+G40 | H44: =H4+H13+H16+H21+H24+H28+H31+H40 | I44: =I4+I13+I16+I21+I24+I28+I31+I40
A46: 【 ② 収 入（売上・粗利・雑収入など） 】
B47: ▶ 収入・支出項目 | C47: =SUM(C48:C54) | D47: =SUM(D48:D54) | E47: =SUM(E48:E54) | F47: =SUM(F48:F54) | G47: =SUM(G48:G54) | H47: =SUM(H48:H54) | I47: =SUM(I48:I54)
A48: 20 | B48: サービス訓練費 | C48: 1120500 | D48: 1014400 | E48: 1260140 | F48: 1251470 | G48: 1259670 | H48: 1313220 | I48: =SUM(C48:H48)
B49: 辻カッティング | C49: 29819 | D49: 37395 | E49: 17943 | G49: 64776 | I49: =SUM(C49:H49)
...

Sheet ウェルピア山県_下期_1-6月
A1: ③ ウェルピア山県 月間収支まとめ 下期_1-6月
A2: 日 | B2: 項目 | C2: R8.1月 | D2: R8.2月 | E2: R8.3月 | F2: R8.4月 | G2: R8.5月 | H2: R8.6月 | I2: 下期累計 | J2: 上期累計 | K2: 通期合計
A3: 【 支 出 】
B4: ▶ 給与 福利 | C4: =SUM(C5:C12) | D4: =SUM(D5:D12) | E4: =SUM(E5:E12) | F4: =SUM(F5:F12) | G4: =SUM(G5:G12) | H4: =SUM(H5:H12) | I4: =SUM(I5:I12) | J4: =SUM(J5:J12) | K4: =SUM(K5:K12)
B5: AJ出向費 | C5: 110000 | D5: 110000 | E5: 110000 | F5: 110000 | G5: 110000 | I5: =SUM(C5:H5) | J5: ='ウェルピア山県_上期_7-12月'!I8 | K5: =I5+J5
A6: 20 | B6: 給与 | C6: 614903 | D6: 640726 | E6: 593725 | F6: 620629 | I6: =SUM(C6:H6) | J6: ='ウェルピア山県_上期_7-12月'!I5 | K6: =I6+J6
A7: 31 | B7: 社員社保料（会社負担分） | C7: 66143 | D7: 66285 | E7: 66026 | F7: 65934 | I7: =SUM(C7:H7) | J7: ='ウェルピア山県_上期_7-12月'!I6 | K7: =I7+J7
A8: 20 | B8: 利用者 工賃 業務委託料 | C8: 226872 | D8: 207594 | E8: 219453 | F8: 302000 | I8: =SUM(C8:H8) | J8: ='ウェルピア山県_上期_7-12月'!I7 | K8: =I8+J8
B9: 出前弁当 | C9: 66528 | D9: 61776 | E9: 77457 | F9: 86011 | I9: =SUM(C9:H9) | J9: ='ウェルピア山県_上期_7-12月'!I9 | K9: =I9+J9
B10: 労働保険料（9.11.2.） | I10: =SUM(C10:H10) | J10: ='ウェルピア山県_上期_7-12月'!I10 | K10: =I10+J10
B11: 増田医院 健康診断 | I11: =SUM(C11:H11) | J11: ='ウェルピア山県_上期_7-12月'!I11 | K11: =I11+J11
B13: ▶ 地代家賃/水光熱/固定資産 | C13: =SUM(C14:C15) | D13: =SUM(D14:D15) | E13: =SUM(E14:E15) | F13: =SUM(F14:F15) | G13: =SUM(G14:G15) | H13: =SUM(H14:H15) | I13: =SUM(I14:I15) | J13: =SUM(J14:J15) | K13: =SUM(K14:K15)
A14: 末 | B14: 矢崎商店 家賃・高熱費 | C14: 180000 | D14: 180000 | E14: 180000 | F14: 180000 | G14: 180000 | I14: =SUM(C14:H14) | J14: ='ウェルピア山県_上期_7-12月'!I14 | K14: =I14+J14
B16: ▶ 顧問料 支払手数料 | C16: =SUM(C17:C20) | D16: =SUM(D17:D20) | E16: =SUM(E17:E20) | F16: =SUM(F17:F20) | G16: =SUM(G17:G20) | H16: =SUM(H17:H20) | I16: =SUM(I17:I20) | J16: =SUM(J17:J20) | K16: =SUM(K17:K20)
A17: 28 | B17: ブリックス 税務 | C17: 12500 | D17: 12500 | E17: 12500 | F17: 12500 | G17: 12500 | I17: =SUM(C17:H17) | J17: ='ウェルピア山県_上期_7-12月'!I17 | K17: =I17+J17
B18: ブリックス給与計算 | C18: 8750 | D18: 8750 | E18: 8750 | F18: 8750 | G18: 8750 | I18: =SUM(C18:H18) | J18: ='ウェルピア山県_上期_7-12月'!I18 | K18: =I18+J18
B19: 沼田行政書士 | C19: 10000 | D19: 10000 | E19: 10000 | F19: 10000 | G19: 10000 | I19: =SUM(C19:H19) | J19: ='ウェルピア山県_上期_7-12月'!I19 | K19: =I19+J19
B21: ▶ リース料 | C21: =SUM(C22:C23) | D21: =SUM(D22:D23) | E21: =SUM(E22:E23) | F21: =SUM(F22:F23) | G21: =SUM(G22:G23) | H21: =SUM(H22:H23) | I21: =SUM(I22:I23) | J21: =SUM(J22:J23) | K21: =SUM(K22:K23)
B22: しんきんリース ｺﾋﾟｰ機 | C22: 13860 | D22: 13860 | E22: 13860 | F22: 13860 | G22: 13860 | I22: =SUM(C22:H22) | J22: ='ウェルピア山県_上期_7-12月'!I22 | K22: =I22+J22
B24: ▶ 通信費 | C24: =SUM(C25:C27) | D24: =SUM(D25:D27) | E24: =SUM(E25:E27) | F24: =SUM(F25:F27) | G24: =SUM(G25:G27) | H24: =SUM(H25:H27) | I24: =SUM(I25:I27) | J24: =SUM(J25:J27) | K24: =SUM(K25:K27)
A25: 末 | B25: ゴラック カウンター | C25: 1069 | E25: 965 | F25: 743 | I25: =SUM(C25:H25) | J25: ='ウェルピア山県_上期_7-12月'!I25 | K25: =I25+J25
B26: テレマーカー | C26: 7879 | D26: 8017 | E26: 7753 | I26: =SUM(C26:H26) | J26: ='ウェルピア山県_上期_7-12月'!I26 | K26: =I26+J26
B28: ▶ 車両費 | C28: =SUM(C29:C30) | D28: =SUM(D29:D30) | E28: =SUM(E29:E30) | F28: =SUM(F29:F30) | G28: =SUM(G29:G30) | H28: =SUM(H29:H30) | I28: =SUM(I29:I30) | J28: =SUM(J29:J30) | K28: =SUM(K29:K30)
B29: 大日 車６台携帯２台貸与 | C29: 110000 | D29: 110000 | E29: 110000 | F29: 110000 | G29: 110000 | I29: =SUM(C29:H29) | J29: ='ウェルピア山県_上期_7-12月'!I29 | K29: =I29+J29
B31: ▶ 雑費/消耗品 | C31: =SUM(C32:C40) | D31: =SUM(D32:D40) | E31: =SUM(E32:E40) | F31: =SUM(F32:F40) | G31: =SUM(G32:G40) | H31: =SUM(H32:H40) | I31: =SUM(I32:I40) | J31: =SUM(J32:J40) | K31: =SUM(K32:K40)
B32: BIZバンク 利用料 | C32: 1620 | D32: 1620 | E32: 1620 | F32: 1620 | G32: 1620 | I32: =SUM(C32:H32) | J32: ='ウェルピア山県_上期_7-12月'!I32 | K32: =I32+J32
B33: 中島清掃 | C33: 2200 | D33: 2200 | E33: 2200 | F33: 2200 | G33: 2200 | I33: =SUM(C33:H33) | J33: ='ウェルピア山県_上期_7-12月'!I35 | K33: =I33+J33
B34: リクルート 勤怠管理 | C34: 16500 | E34: 16500 | F34: 16500 | G34: 16500 | I34: =SUM(C34:H34) | J34: ='ウェルピア山県_上期_7-12月'!I33 | K34: =I34+J34
B35: リクルート 募集 | I35: =SUM(C35:H35) | J35: ='ウェルピア山県_上期_7-12月'!I34 | K35: =I35+J35
A36: 10 | B36: 小口現金 | C36: 100000 | E36: 100000 | I36: =SUM(C36:H36) | J36: ='ウェルピア山県_上期_7-12月'!I37 | K36: =I36+J36
B37: 清芳屋 | E37: 6712 | F37: 9035 | I37: =SUM(C37:H37) | J37: ='ウェルピア山県_上期_7-12月'!I36 | K37: =I37+J37
B38: モノタロウ | C38: 8567 | I38: =SUM(C38:H38) | J38: ='ウェルピア山県_上期_7-12月'!I38 | K38: =I38+J38
B39: ノウビー 勤怠管理 | D39: 16500 | I39: =SUM(C39:H39) | K39: =I39+J39
B41: ▶ 銀行返済 | C41: =SUM(C42:C47) | D41: =SUM(D42:D47) | E41: =SUM(E42:E47) | F41: =SUM(F42:F47) | G41: =SUM(G42:G47) | H41: =SUM(H42:H47) | I41: =SUM(I42:I47) | J41: =SUM(J42:J47) | K41: =SUM(K42:K47)
B42: 10期累計 | F42: -205296 | G42: -276303 | I42: =SUM(C42:H42) | K42: =I42+J42
B43: 岐信 500万円 84×78 R8.7迄 | C43: 59488 | I43: =SUM(C43:H43) | K43: =I43+J43
B44: 岐信 500万円 84×79 R8.7迄 | D44: 59460 | I44: =SUM(C44:H44) | K44: =I44+J44
B45: 岐信 500万円 84×80 R8.7迄 | E45: 59425 | I45: =SUM(C45:H45) | K45: =I45+J45
B46: 岐信 500万円 84×81 R8.7迄 | F46: 59347 | I46: =SUM(C46:H46) | K46: =I46+J46
B48: ① 支出合計 | C48: =C4+C13+C16+C21+C24+C28+C31+C41 | D48: =D4+D13+D16+D21+D24+D28+D31+D41 | E48: =E4+E13+E16+E21+E24+E28+E31+E41 | F48: =F4+F13+F16+F21+F24+F28+F31+F41 | G48: =G4+G13+G16+G21+G24+G28+G31+G41 | H48: =H4+H13+H16+H21+H24+H28+H31+H41 | I48: =I4+I13+I16+I21+I24+I28+I31+I41 | J48: =J4+J13+J16+J21+J24+J28+J31+J41 | K48: =K4+K13+K16+K21+K24+K28+K31+K41
...

Sheet 大日産業（本社）_上期_7-12月
A1: ④ 大日産業（本社） 月間収支まとめ 上期_7-12月
A2: 日 | B2: 項目 | C2: R7.7月 | D2: R7.8月 | E2: R7.9月 | F2: R7.10月 | G2: R7.11月 | H2: R7.12月 | I2: 累 計
A3: 【 支 出 】
B4: ▶ 給与 | C4: =SUM(C5:C13) | D4: =SUM(D5:D13) | E4: =SUM(E5:E13) | F4: =SUM(F5:F13) | G4: =SUM(G5:G13) | H4: =SUM(H5:H13) | I4: =SUM(I5:I13)
B5: 厚生年金（役員）会社負担 | C5: 57960 | D5: 57960 | E5: 57960 | F5: 57960 | G5: 57960 | H5: 57960 | I5: =SUM(C5:H5)
B6: 厚生年金（役員）会社負担 | E6: 25656 | F6: 24904 | G6: 24967 | H6: 24942 | I6: =SUM(C6:H6)
B7: 長野農研 | C7: 135300 | D7: 127600 | E7: 155650 | F7: 132000 | G7: 129800 | H7: 127600 | I7: =SUM(C7:H7)
B8: パウダーアイス社員 | E8: 302000 | F8: 165228 | G8: 176804 | H8: 172094 | I8: =SUM(C8:H8)
B9: パウダーアイスPA | E9: 400400 | F9: 199632 | I9: =SUM(C9:H9)
A10: 20 | B10: 役員報酬 | F10: 20090 | H10: 500000 | I10: =SUM(C10:H10)
B11: 労働保険 （9.11.2.3） | E11: 281934 | G11: 286539 | I11: =SUM(C11:H11)
A12: 20 | B12: 経理 総務部門 給料（PA） | I12: =SUM(C12:H12)
B14: ▶ 雑費 | C14: =SUM(C15:C40) | D14: =SUM(D15:D40) | E14: =SUM(E15:E40) | F14: =SUM(F15:F40) | G14: =SUM(G15:G40) | H14: =SUM(H15:H40) | I14: =SUM(I15:I40)
A15: 10 | B15: ｼﾝｷﾝJCB ETC ｶﾞｿﾘﾝ代 | C15: 49180 | D15: 33410 | E15: 42840 | F15: 31640 | G15: 19740 | H15: 18070 | I15: =SUM(C15:H15)
A16: 2 | B16: ENEOS ビジネスカード | C16: 39760 | D16: 66150 | E16: 36188 | F16: 56275 | G16: 56093 | H16: 73368 | I16: =SUM(C16:H16)
B17: 振込手数料 | C17: 39215 | D17: 40975 | E17: 37180 | F17: 39930 | G17: 35200 | H17: 41965 | I17: =SUM(C17:H17)
B18: 十六社長カード 交際費 | C18: 40785 | D18: 55173 | E18: 74645 | F18: 35635 | G18: 67369 | H18: 30703 | I18: =SUM(C18:H18)
A19: 3 | B19: 小口現金 本社 | D19: 100000 | E19: 100000 | F19: 100000 | G19: 100000 | H19: 150000 | I19: =SUM(C19:H19)
A20: 20 | B20: 小口現金 | D20: 100000 | G20: 100000 | I20: =SUM(C20:H20)
A21: 6 | B21: セディナ新幹線（社長） | C21: 27070 | D21: 1470 | E21: 62840 | F21: 10780 | I21: =SUM(C21:H21)
B22: 全保連 立替(グットライフ東京） | D22: 112530 | E22: 112530 | F22: 112530 | G22: 112530 | I22: =SUM(C22:H22)
B23: 佐川急便 | C23: 14168 | G23: 3234 | I23: =SUM(C23:H23)
A24: 10 | B24: 大垣園芸 | C24: 44000 | G24: 33000 | I24: =SUM(C24:H24)
A25: 20 | B25: Rサプライ | G25: 9601 | H25: 9601 | I25: =SUM(C25:H25)
B26: ﾔﾏﾄ | G26: 880 | I26: =SUM(C26:H26)
B27: ㈱QuietHills | C27: 10773 | I27: =SUM(C27:H27)
B28: ㈱QuietHills 販売商品 | H28: 6464 | I28: =SUM(C28:H28)
B29: 羽島市観光協会 | C29: 10000 | I29: =SUM(C29:H29)
B30: エムテック防災 | C30: 11000 | I30: =SUM(C30:H30)
B31: トヨタ タイヤ交換 | C31: 6600 | I31: =SUM(C31:H31)
B32: トヨタ シエンタ整備 | H32: 3410 | I32: =SUM(C32:H32)
B33: フルーツ羽島 | E33: 12070 | I33: =SUM(C33:H33)
B34: 伊自良モーターズ | E34: 120592 | I34: =SUM(C34:H34)
B35: ヒーリングエンターテイメント | E35: 6464 | I35: =SUM(C35:H35)
B36: 島区 | G36: 25000 | I36: =SUM(C36:H36)
B37: AJ立替 十六リース | G37: 118140 | I37: =SUM(C37:H37)
B38: ぎふ駅前フェス | G38: 100000 | I38: =SUM(C38:H38)
A39: 20 | B39: 商工会 会費 | H39: 75000 | I39: =SUM(C39:H39)
B41: ▶ 福祉部門 | C41: =SUM(C42:C44) | D41: =SUM(D42:D44) | E41: =SUM(E42:E44) | F41: =SUM(F42:F44) | G41: =SUM(G42:G44) | H41: =SUM(H42:H44) | I41: =SUM(I42:I44)
B42: ウェルピア → 大日就労移行人件費 | C42: 93323 | D42: 97767 | E42: 84554 | F42: 120760 | G42: 208247 | H42: 259690 | I42: =SUM(C42:H42)
...

Sheet 大日産業（本社）_下期_1-6月
A1: ④ 大日産業（本社） 月間収支まとめ 下期_1-6月
A2: 日 | B2: 項目 | C2: R8.1月 | D2: R8.2月 | E2: R8.3月 | F2: R8.4月 | G2: R8.5月 | H2: R8.6月 | I2: 下期累計 | J2: 上期累計 | K2: 通期合計
A3: 【 支 出 】
B4: ▶ 給与 | C4: =SUM(C5:C12) | D4: =SUM(D5:D12) | E4: =SUM(E5:E12) | F4: =SUM(F5:F12) | G4: =SUM(G5:G12) | H4: =SUM(H5:H12) | I4: =SUM(I5:I12) | J4: =SUM(J5:J12) | K4: =SUM(K5:K12)
A5: 20 | B5: 役員報酬 | C5: 500000 | D5: 500000 | E5: 500000 | F5: 500000 | G5: 500000 | I5: =SUM(C5:H5) | J5: ='大日産業（本社）_上期_7-12月'!I10 | K5: =I5+J5
B6: 厚生年金（役員）会社負担 | C6: 57960 | D6: 57960 | E6: 57960 | F6: 57716 | I6: =SUM(C6:H6) | J6: ='大日産業（本社）_上期_7-12月'!I5 | K6: =I6+J6
B7: 厚生年金（役員）会社負担 | C7: 24877 | D7: 24959 | E7: 24994 | F7: 25381 | I7: =SUM(C7:H7) | J7: ='大日産業（本社）_上期_7-12月'!I6 | K7: =I7+J7
B8: パウダーアイス社員 | C8: 160303 | D8: 175238 | E8: 181654 | F8: 271961 | I8: =SUM(C8:H8) | J8: ='大日産業（本社）_上期_7-12月'!I8 | K8: =I8+J8
B9: 長野農研 | C9: 130900 | D9: 101200 | E9: 95700 | F9: 143000 | I9: =SUM(C9:H9) | J9: ='大日産業（本社）_上期_7-12月'!I7 | K9: =I9+J9
B10: 労働保険 （9.11.2.3） | D10: 286539 | I10: =SUM(C10:H10) | J10: ='大日産業（本社）_上期_7-12月'!I11 | K10: =I10+J10
A11: 20 | B11: 経理 総務部門 給料（PA） | I11: =SUM(C11:H11) | J11: ='大日産業（本社）_上期_7-12月'!I12 | K11: =I11+J11
B13: ▶ 雑費 | C13: =SUM(C14:C33) | D13: =SUM(D14:D33) | E13: =SUM(E14:E33) | F13: =SUM(F14:F33) | G13: =SUM(G14:G33) | H13: =SUM(H14:H33) | I13: =SUM(I14:I33) | J13: =SUM(J14:J33) | K13: =SUM(K14:K33)
A14: 10 | B14: ｼﾝｷﾝJCB ETC ｶﾞｿﾘﾝ代 | C14: 38880 | D14: 68680 | E14: 23200 | F14: 82270 | I14: =SUM(C14:H14) | J14: ='大日産業（本社）_上期_7-12月'!I15 | K14: =I14+J14
A15: 2 | B15: ENEOS ビジネスカード | C15: 34825 | D15: 90553 | E15: 74805 | F15: 53347 | I15: =SUM(C15:H15) | J15: ='大日産業（本社）_上期_7-12月'!I16 | K15: =I15+J15
B16: 振込手数料 | C16: 35530 | D16: 32890 | E16: 32780 | F16: 32285 | I16: =SUM(C16:H16) | J16: ='大日産業（本社）_上期_7-12月'!I17 | K16: =I16+J16
B17: 十六社長カード 交際費 | C17: 46986 | D17: 124717 | E17: 24332 | F17: 69621 | I17: =SUM(C17:H17) | J17: ='大日産業（本社）_上期_7-12月'!I18 | K17: =I17+J17
A18: 21 | B18: 小口現金 本社 | C18: 100000 | D18: 150000 | E18: 100000 | I18: =SUM(C18:H18) | J18: ='大日産業（本社）_上期_7-12月'!I19 | K18: =I18+J18
A19: 26 | B19: 小口現金 | E19: 150000 | I19: =SUM(C19:H19) | J19: ='大日産業（本社）_上期_7-12月'!I20 | K19: =I19+J19
A20: 6 | B20: セディナ新幹線（社長） | G20: 25750 | I20: =SUM(C20:H20) | J20: ='大日産業（本社）_上期_7-12月'!I21 | K20: =I20+J20
A21: 10 | B21: 竹花園 葉牡丹 | C21: 28600 | I21: =SUM(C21:H21) | K21: =I21+J21
B22: 瀬古花 しめ縄 | C22: 26620 | I22: =SUM(C22:H22) | K22: =I22+J22
B23: 商工会 健康診断 | C23: 177600 | I23: =SUM(C23:H23) | K23: =I23+J23
A24: 20 | B24: フルーツ羽島 御歳暮 | C24: 238770 | I24: =SUM(C24:H24) | K24: =I24+J24
A25: 30 | B25: 年賀状 | C25: 30470 | I25: =SUM(C25:H25) | K25: =I25+J25
B26: Rサプライ | C26: 24003 | I26: =SUM(C26:H26) | J26: ='大日産業（本社）_上期_7-12月'!I25 | K26: =I26+J26
A27: 20 | B27: エムテック | D27: 11000 | I27: =SUM(C27:H27) | K27: =I27+J27
A28: 20 | B28: 三甲ゴルフ | E28: 66000 | I28: =SUM(C28:H28) | K28: =I28+J28
B29: トヨペット 車検 | E29: 148313 | I29: =SUM(C29:H29) | K29: =I29+J29
A30: 20 | B30: 伊自良モーター プリウス車検 | F30: 150983 | I30: =SUM(C30:H30) | K30: =I30+J30
B31: ﾔﾏﾄ | I31: =SUM(C31:H31) | J31: ='大日産業（本社）_上期_7-12月'!I26 | K31: =I31+J31
B32: 佐川急便 | I32: =SUM(C32:H32) | J32: ='大日産業（本社）_上期_7-12月'!I23 | K32: =I32+J32
B34: ▶ 福祉部門 | C34: =SUM(C35:C38) | D34: =SUM(D35:D38) | E34: =SUM(E35:E38) | F34: =SUM(F35:F38) | G34: =SUM(G35:G38) | H34: =SUM(H35:H38) | I34: =SUM(I35:I38) | J34: =SUM(J35:J38) | K34: =SUM(K35:K38)
B35: ウェルピア業務委託費へ（羽島） | C35: 650000 | D35: 650000 | E35: 650000 | F35: 650000 | G35: 650000 | I35: =SUM(C35:H35) | J35: ='大日産業（本社）_上期_7-12月'!I43 | K35: =I35+J35
B36: ウェルピア → 大日就労移行人件費 | C36: 184850 | D36: 171530 | E36: 287368 | F36: 201344 | I36: =SUM(C36:H36) | J36: ='大日産業（本社）_上期_7-12月'!I42 | K36: =I36+J36
B37: 中部 トーカイサーモ サカエ等 | F37: 564935 | I37: =SUM(C37:H37) | K37: =I37+J37
B39: ▶ 銀行返済 | C39: =SUM(C40:C41) | D39: =SUM(D40:D41) | E39: =SUM(E40:E41) | F39: =SUM(F40:F41) | G39: =SUM(G40:G41) | H39: =SUM(H40:H41) | I39: =SUM(I40:I41) | J39: =SUM(J40:J41) | K39: =SUM(K40:K41)
A40: 25 | B40: 岐信 2400万 アクトス（7回〜10回） | C40: 225017 | D40: 221843 | E40: 228507 | F40: 227097 | I40: =SUM(C40:H40) | J40: ='大日産業（本社）_上期_7-12月'!I46 | K40: =I40+J40
B42: ▶ 顧問料 定額雑費 | C42: =SUM(C43:C51) | D42: =SUM(D43:D51) | E42: =SUM(E43:E51) | F42: =SUM(F43:F51) | G42: =SUM(G43:G51) | H42: =SUM(H43:H51) | I42: =SUM(I43:I51) | J42: =SUM(J43:J51) | K42: =SUM(K43:K51)
A43: 31 | B43: 高橋弁護士事務所 | C43: 20540 | D43: 20540 | E43: 20540 | F43: 20540 | G43: 20540 | I43: =SUM(C43:H43) | J43: ='大日産業（本社）_上期_7-12月'!I52 | K43: =I43+J43
A44: 15 | B44: ギフシン.大共ネットバンク | C44: 6600 | D44: 6600 | E44: 6600 | F44: 6600 | G44: 6600 | I44: =SUM(C44:H44) | J44: ='大日産業（本社）_上期_7-12月'!I53 | K44: =I44+J44
...

Sheet 大日産業（不動産）_上期_7-12月
A1: ⑤ 大日産業（不動産部門） 月間収支まとめ 上期_7-12月
A2: 日 | B2: 項目 | C2: R7.7月 | D2: R7.8月 | E2: R7.9月 | F2: R7.10月 | G2: R7.11月 | H2: R7.12月 | I2: 累 計
A3: 【 支 出 】
B4: ▶ 不動産岐信（普）で支払い | C4: =SUM(C5:C36) | D4: =SUM(D5:D36) | E4: =SUM(E5:E36) | F4: =SUM(F5:F36) | G4: =SUM(G5:G36) | H4: =SUM(H5:H36) | I4: =SUM(I5:I36)
A5: 20 | B5: 1億5千万 レジデンス（96回〜101回） | C5: 778295 | D5: 777146 | E5: 771739 | F5: 774849 | G5: 769516 | H5: 772551 | I5: =SUM(C5:H5)
A6: 25 | B6: 1750万円 安田（53回〜58回） | C6: 117940 | D6: 117776 | E6: 116947 | F6: 117447 | G6: 116629 | H6: 117119 | I6: =SUM(C6:H6)
B7: 1500万円 南谷（48回〜53回） | C7: 101665 | D7: 101524 | E7: 100791 | F7: 101243 | G7: 100518 | H7: 100962 | I7: =SUM(C7:H7)
A8: 末 | B8: 9800万円 51.52街区（101回〜106回） | C8: 509292 | D8: 505320 | E8: 507836 | F8: 503911 | G8: 506381 | H8: 505653 | I8: =SUM(C8:H8)
B9: 6000万円 BLOCK４７（32回〜37回） | C9: 340550 | D9: 337454 | E9: 339721 | F9: 336651 | G9: 338891 | H9: 338477 | I9: =SUM(C9:H9)
B10: 岐信 積金分（テナント保証金） | C10: 100000 | D10: 100000 | E10: 100000 | F10: 100000 | G10: 100000 | H10: 100000 | I10: =SUM(C10:H10)
B11: BLOCK47 電気料金 | C11: 45800 | D11: 50676 | E11: 50192 | F11: 39319 | G11: 40660 | H11: 38959 | I11: =SUM(C11:H11)
B12: BLOCK47 ガス料金（空調） | C12: 14684 | D12: 48321 | E12: 68049 | F12: 62632 | G12: 25100 | H12: 3456 | I12: =SUM(C12:H12)
B13: BLOCK47 通信 テレマーカー | C13: 26166 | D13: 26147 | E13: 25850 | F13: 25582 | G13: 25514 | H13: 25584 | I13: =SUM(C13:H13)
B14: BLOCK47 Wi-Fi NTT（テレマーカー） | C14: 15950 | D14: 15950 | E14: 15950 | F14: 15950 | G14: 15950 | H14: 15950 | I14: =SUM(C14:H14)
A15: 26 | B15: BLOCK ALSOK 入金機 | C15: 62150 | D15: 62150 | E15: 62150 | F15: 62150 | G15: 62150 | H15: 62150 | I15: =SUM(C15:H15)
B16: BLOCK ALSOK 施設警備 | C16: 21450 | D16: 21450 | E16: 21450 | F16: 21450 | G16: 21450 | H16: 21450 | I16: =SUM(C16:H16)
B17: BLOCK47 水道料金(オフィス） | E17: 20364 | F17: 20364 | G17: 5258 | I17: =SUM(C17:H17)
B18: BLOCK47 ガス料金（給湯） | F18: 226 | I18: =SUM(C18:H18)
B19: BLOCK47 水道料金(共用部） | G19: 20631 | I19: =SUM(C19:H19)
A20: 6 | B20: 東芝エレベーター（保守） | C20: 14300 | D20: 14300 | E20: 14300 | F20: 14300 | G20: 14300 | H20: 14300 | I20: =SUM(C20:H20)
A21: 27 | B21: オリエント O2 71回払い | C21: 60500 | D21: 60500 | E21: 60500 | F21: 60500 | G21: 60500 | H21: 60500 | I21: =SUM(C21:H21)
A22: 28 | B22: 電気料 不動産共用部 など | C22: 55079 | D22: 59432 | E22: 53156 | G22: 15373 | H22: 46599 | I22: =SUM(C22:H22)
A23: 末 | B23: 1400万円 ウェルピア（89回〜92回） | C23: 121931 | D23: 121559 | E23: 121557 | F23: 121197 | I23: =SUM(C23:H23)
B24: 覚建築（1回〜2回） | C24: 305000 | D24: 300000 | I24: =SUM(C24:H24)
B25: 全保連 立替(グットライフ東京） | C25: 115720 | I25: =SUM(C25:H25)
B26: 加藤造園 | C26: 45100 | I26: =SUM(C26:H26)
B27: NP パンフレット | C27: 2844 | I27: =SUM(C27:H27)
B28: マルナカ建設 | C28: 39600 | I28: =SUM(C28:H28)
B29: ネットプロテクション | C29: 2844 | I29: =SUM(C29:H29)
B30: 水道受益者負担金 年4回（7.9.12.2） | E30: 18810 | I30: =SUM(C30:H30)
B31: なるおかサイクル 盆踊り景品 | F31: 35970 | I31: =SUM(C31:H31)
B32: 高橋弁護士 | G32: 319380 | I32: =SUM(C32:H32)
B33: EC協賛金 | G33: 5000 | I33: =SUM(C33:H33)
B34: はしまる | H34: 11000 | I34: =SUM(C34:H34)
B35: 施設全体USEN （5月100.980円） | I35: =SUM(C35:H35)
B37: ▶ 商信 自動振替 | C37: =SUM(C38:C42) | D37: =SUM(D38:D42) | E37: =SUM(E38:E42) | F37: =SUM(F38:F42) | G37: =SUM(G38:G42) | H37: =SUM(H38:H42) | I37: =SUM(I38:I42)
A38: 20 | B38: 1900万円 46街区 事務所（87回〜92回） | C38: 161448 | D38: 161213 | E38: 160882 | F38: 160743 | G38: 160427 | H38: 160274 | I38: =SUM(C38:H38)
A39: 20 | B39: 5800万円 温しゃぶ（73回〜78回） | C39: 301948 | D39: 301588 | E39: 299318 | F39: 300869 | G39: 298662 | H39: 300150 | I39: =SUM(C39:H39)
A40: 末 | B40: 6000万円 BLOCK４７（32回〜37回） | C40: 333954 | D40: 333572 | E40: 330733 | F40: 332808 | G40: 329993 | H40: 332044 | I40: =SUM(C40:H40)
B41: 1700万円 消費税（8回〜12回） | C41: 1500000 | D41: 1500000 | E41: 1400000 | F41: 1400000 | I41: =SUM(C41:H41)
...

Sheet 大日産業（不動産）_下期_1-6月
A1: ⑤ 大日産業（不動産部門） 月間収支まとめ 下期_1-6月
A2: 日 | B2: 項目 | C2: R8.1月 | D2: R8.2月 | E2: R8.3月 | F2: R8.4月 | G2: R8.5月 | H2: R8.6月 | I2: 下期累計 | J2: 上期累計 | K2: 通期合計
A3: 【 支 出 】
B4: ▶ 不動産岐信（普）で支払い | C4: =SUM(C5:C31) | D4: =SUM(D5:D31) | E4: =SUM(E5:E31) | F4: =SUM(F5:F31) | G4: =SUM(G5:G31) | H4: =SUM(H5:H31) | I4: =SUM(I5:I31) | J4: =SUM(J5:J31) | K4: =SUM(K5:K31)
A5: 20 | B5: 1億5千万 レジデンス（102回〜105回） | C5: 771403 | D5: 758036 | E5: 783999 | F5: 778239 | I5: =SUM(C5:H5) | J5: ='大日産業（不動産）_上期_7-12月'!I5 | K5: =I5+J5
A6: 25 | B6: 1750万円 安田（59回〜62回） | C6: 116954 | D6: 114875 | E6: 119085 | F6: 118194 | I6: =SUM(C6:H6) | J6: ='大日産業（不動産）_上期_7-12月'!I6 | K6: =I6+J6
B7: 1500万円 南谷（54回〜57回） | C7: 100821 | D7: 98969 | E7: 102738 | F7: 101948 | I7: =SUM(C7:H7) | J7: ='大日産業（不動産）_上期_7-12月'!I7 | K7: =I7+J7
A8: 末 | B8: 9800万円 51.52街区（107回〜110回） | C8: 495545 | D8: 504198 | E8: 511389 | F8: 514021 | I8: =SUM(C8:H8) | J8: ='大日産業（不動産）_上期_7-12月'!I8 | K8: =I8+J8
B9: 6000万円 BLOCK４７（38回〜41回） | C9: 330217 | D9: 337647 | E9: 344861 | F9: 347320 | I9: =SUM(C9:H9) | J9: ='大日産業（不動産）_上期_7-12月'!I9 | K9: =I9+J9
B10: 岐信 積金分（テナント保証金） | C10: 100000 | D10: 100000 | E10: 100000 | F10: 100000 | I10: =SUM(C10:H10) | J10: ='大日産業（不動産）_上期_7-12月'!I10 | K10: =I10+J10
A11: 28 | B11: 電気料 不動産共用部 など | C11: 58212 | D11: 42688 | E11: 37791 | I11: =SUM(C11:H11) | J11: ='大日産業（不動産）_上期_7-12月'!I22 | K11: =I11+J11
B12: BLOCK47 電気料金 | C12: 39207 | D12: 37001 | E12: 34123 | I12: =SUM(C12:H12) | J12: ='大日産業（不動産）_上期_7-12月'!I11 | K12: =I12+J12
B13: BLOCK47 ガス料金（空調） | C13: 9623 | D13: 20351 | E13: 44623 | I13: =SUM(C13:H13) | J13: ='大日産業（不動産）_上期_7-12月'!I12 | K13: =I13+J13
B14: BLOCK47 通信 テレマーカー | C14: 24696 | D14: 24659 | E14: 251289 | I14: =SUM(C14:H14) | J14: ='大日産業（不動産）_上期_7-12月'!I13 | K14: =I14+J14
B15: BLOCK47 Wi-Fi NTT（テレマーカー） | C15: 15950 | D15: 15950 | E15: 15950 | I15: =SUM(C15:H15) | J15: ='大日産業（不動産）_上期_7-12月'!I14 | K15: =I15+J15
A16: 26 | B16: BLOCK ALSOK 入金機 | C16: 62150 | D16: 62150 | E16: 62150 | I16: =SUM(C16:H16) | J16: ='大日産業（不動産）_上期_7-12月'!I15 | K16: =I16+J16
B17: BLOCK ALSOK 施設警備 | C17: 21450 | D17: 21450 | E17: 21450 | I17: =SUM(C17:H17) | J17: ='大日産業（不動産）_上期_7-12月'!I16 | K17: =I17+J17
B18: BLOCK47 ガス料金（給湯） | C18: 20351 | I18: =SUM(C18:H18) | J18: ='大日産業（不動産）_上期_7-12月'!I18 | K18: =I18+J18
B19: BLOCK47 水道料金(オフィス） | C19: 5258 | I19: =SUM(C19:H19) | J19: ='大日産業（不動産）_上期_7-12月'!I17 | K19: =I19+J19
B20: BLOCK47 水道料金(共用部） | C20: 13776 | I20: =SUM(C20:H20) | J20: ='大日産業（不動産）_上期_7-12月'!I19 | K20: =I20+J20
A21: 6 | B21: 東芝エレベーター（保守） | C21: 14300 | D21: 14300 | E21: 14300 | I21: =SUM(C21:H21) | J21: ='大日産業（不動産）_上期_7-12月'!I20 | K21: =I21+J21
A22: 27 | B22: オリエント O2 71回払い | C22: 60500 | D22: 60500 | E22: 60500 | I22: =SUM(C22:H22) | J22: ='大日産業（不動産）_上期_7-12月'!I21 | K22: =I22+J22
B23: 加藤造園 | C23: 85580 | I23: =SUM(C23:H23) | J23: ='大日産業（不動産）_上期_7-12月'!I26 | K23: =I23+J23
A24: 10 | B24: はしまなごみスポーツ協賛 | D24: 5000 | I24: =SUM(C24:H24) | K24: =I24+J24
A25: 20 | B25: ネットプロテクション | D25: 3205 | I25: =SUM(C25:H25) | J25: ='大日産業（不動産）_上期_7-12月'!I29 | K25: =I25+J25
A26: 30 | B26: オノデン | D26: 55000 | I26: =SUM(C26:H26) | K26: =I26+J26
B27: アクシス フェンス | E27: 44000 | I27: =SUM(C27:H27) | K27: =I27+J27
B28: アクシス くろぎ とんこつ ドア | E28: 990000 | I28: =SUM(C28:H28) | K28: =I28+J28
B29: アドアップ 看板 麻辣湯 | E29: 71500 | I29: =SUM(C29:H29) | K29: =I29+J29
B30: 覚建築 アサイ | E30: 73700 | I30: =SUM(C30:H30) | K30: =I30+J30
B32: ▶ 商信 自動振替 | C32: =SUM(C33:C36) | D32: =SUM(D33:D36) | E32: =SUM(E33:E36) | F32: =SUM(F33:F36) | G32: =SUM(G33:G36) | H32: =SUM(H33:H36) | I32: =SUM(I33:I36) | J32: =SUM(J33:J36) | K32: =SUM(K33:K36)
A33: 20 | B33: 1900万円 46街区 事務所（93回〜96回） | C33: 160039 | D33: 159629 | E33: 159569 | F33: 159291 | I33: =SUM(C33:H33) | J33: ='大日産業（不動産）_上期_7-12月'!I38 | K33: =I33+J33
A34: 20 | B34: 5800万円 温しゃぶ（79回〜82回） | C34: 299790 | D34: 293872 | E34: 299071 | F34: 296881 | I34: =SUM(C34:H34) | J34: ='大日産業（不動産）_上期_7-12月'!I39 | K34: =I34+J34
A35: 末 | B35: 6000万円 BLOCK４７（38回〜41回） | C35: 331662 | D35: 324092 | E35: 330898 | F35: 328145 | I35: =SUM(C35:H35) | J35: ='大日産業（不動産）_上期_7-12月'!I40 | K35: =I35+J35
B37: ▶ 当座立替払い | C37: =SUM(C38:C60) | D37: =SUM(D38:D60) | E37: =SUM(E38:E60) | F37: =SUM(F38:F60) | G37: =SUM(G38:G60) | H37: =SUM(H38:H60) | I37: =SUM(I38:I60) | J37: =SUM(J38:J60) | K37: =SUM(K38:K60)
A38: 20 | B38: BLOCK47 中部電気保安協会 | C38: 16511 | D38: 16511 | E38: 16511 | F38: 16511 | G38: 16511 | I38: =SUM(C38:H38) | J38: ='大日産業（不動産）_上期_7-12月'!I44 | K38: =I38+J38
A39: 末 | B39: BLOCK４７ 複合機 ゴラック | C39: 1521 | D39: 912 | E39: 2739 | F39: 8041 | I39: =SUM(C39:H39) | J39: ='大日産業（不動産）_上期_7-12月'!I45 | K39: =I39+J39
B40: しんきんBLOCK47２F 複合機60回 | C40: 10670 | I40: =SUM(C40:H40) | J40: ='大日産業（不動産）_上期_7-12月'!I46 | K40: =I40+J40
B41: BLOCK保険 月払 50380/2600 | C41: 50380 | I41: =SUM(C41:H41) | K41: =I41+J41
A42: 末 | B42: 桑名セブンイレブン家賃収入 | C42: 313550 | D42: 313550 | E42: 313550 | F42: 313550 | G42: 313550 | I42: =SUM(C42:H42) | J42: ='大日産業（不動産）_上期_7-12月'!I47 | K42: =I42+J42
...

Sheet Eats_上期_7-12月
A1: ⑥ Eats 月間収支まとめ 上期_7-12月
A2: 日 | B2: 項目 | C2: R7.7月 | D2: R7.8月 | E2: R7.9月 | F2: R7.10月 | G2: R7.11月 | H2: R7.12月 | I2: 累 計
A3: 【 支 出 】
B4: ▶ 給与・法定福利・福利 | C4: =SUM(C5:C13) | D4: =SUM(D5:D13) | E4: =SUM(E5:E13) | F4: =SUM(F5:F13) | G4: =SUM(G5:G13) | H4: =SUM(H5:H13) | I4: =SUM(I5:I13)
A5: 20 | B5: 給与支給 社員 | C5: 882833 | D5: 889119 | E5: 918610 | F5: 595145 | G5: 167615 | I5: =SUM(C5:H5)
A6: 20 | B6: 給与支給 PA | C6: 423046 | D6: 457105 | E6: 490574 | F6: 243950 | I6: =SUM(C6:H6)
A7: 20 | B7: 社会保険 社員 会社負担 | C7: 126244 | D7: 126279 | E7: 126578 | F7: 42795 | I7: =SUM(C7:H7)
A8: 20 | B8: 社会保険 PA 会社負担 | C8: 29291 | D8: 29343 | E8: 29518 | I8: =SUM(C8:H8)
A9: 末 | B9: 業務委託費 | E9: 577233 | F9: 1112486 | G9: 1059267 | H9: 272917 | I9: =SUM(C9:H9)
A10: 末 | B10: 業務委託費 | F10: 1179831 | G10: 454870 | H10: 1194939 | I10: =SUM(C10:H10)
A11: 末 | B11: 杉山氏 交通費（1/3） | C11: 33158 | F11: 79580 | H11: 107252 | I11: =SUM(C11:H11)
A12: 20 | B12: 家田氏 業務委託費 | C12: 100000 | I12: =SUM(C12:H12)
B14: ▶ 光熱費 | C14: =SUM(C15:C19) | D14: =SUM(D15:D19) | E14: =SUM(E15:E19) | F14: =SUM(F15:F19) | G14: =SUM(G15:G19) | H14: =SUM(H15:H19) | I14: =SUM(I15:I19)
B15: 電気 | C15: 158731 | D15: 175165 | E15: 172146 | F15: 134202 | G15: 138528 | H15: 130500 | I15: =SUM(C15:H15)
B16: ガス 空調 | C16: 24153 | D16: 106930 | E16: 152434 | F16: 122679 | G16: 46121 | H16: 18171 | I16: =SUM(C16:H16)
B17: ガス 厨房 | C17: 29745 | D17: 28422 | E17: 34553 | F17: 27954 | G17: 19089 | H17: 24514 | I17: =SUM(C17:H17)
B18: 水道 | E18: 34540 | F18: 34540 | G18: 23892 | I18: =SUM(C18:H18)
B20: ▶ 銀行返済 | C20: =SUM(C21:C24) | D20: =SUM(D21:D24) | E20: =SUM(E21:E24) | F20: =SUM(F21:F24) | G20: =SUM(G21:G24) | H20: =SUM(H21:H24) | I20: =SUM(I21:I24)
B21: 3000万 商工中金 | C21: 516083 | D21: 515457 | E21: 515600 | F21: 512709 | G21: 512852 | H21: 513663 | I21: =SUM(C21:H21)
A22: 20 | B22: 商工中金5千万R17.9迄（58回〜60回） | C22: 314407 | D22: 314122 | E22: 312745 | I22: =SUM(C22:H22)
A23: 25 | B23: 岐信 4000万 R7.7～（4回〜6回） | F23: 416797 | G23: 414892 | H23: 415914 | I23: =SUM(C23:H23)
B25: ▶ 食材仕入れ | C25: =SUM(C26:C42) | D25: =SUM(D26:D42) | E25: =SUM(E26:E42) | F25: =SUM(F26:F42) | G25: =SUM(G26:G42) | H25: =SUM(H26:H42) | I25: =SUM(I26:I42)
B26: 大光 | C26: 102837 | D26: 153214 | E26: 94651 | F26: 60285 | G26: 46369 | H26: 28549 | I26: =SUM(C26:H26)
B27: 高瀬物産 仕入 | C27: 87408 | D27: 74751 | E27: 118008 | F27: 44700 | G27: 92826 | H27: 64604 | I27: =SUM(C27:H27)
B28: 名古屋製酪 仕入 | C28: 66314 | D28: 93693 | E28: 61434 | F28: 41505 | G28: 55911 | H28: 41005 | I28: =SUM(C28:H28)
B29: マルト水谷 仕入 | C29: 252020 | D29: 346519 | E29: 312826 | F29: 127100 | G29: 244488 | H29: 217684 | I29: =SUM(C29:H29)
B30: 丸福商店 仕入 | C30: 130491 | D30: 153093 | E30: 171559 | F30: 49978 | G30: 9210 | H30: 18333 | I30: =SUM(C30:H30)
B31: 奥田庄司 商店 | C31: 25600 | D31: 43200 | E31: 38400 | F31: 25600 | H31: 20790 | I31: =SUM(C31:H31)
A32: 15 | B32: 小口 店舗 | C32: 200000 | D32: 180000 | F32: 200000 | G32: 200000 | H32: 300000 | I32: =SUM(C32:H32)
A33: 24 | B33: 小口 店舗 | F33: 50000 | I33: =SUM(C33:H33)
A34: 末 | B34: 浅野 純也 仕入 | D34: 161267 | E34: 2600 | F34: 32855 | G34: 44500 | H34: 43254 | I34: =SUM(C34:H34)
A35: 15 | B35: 小口 本社 | C35: 100000 | F35: 100000 | I35: =SUM(C35:H35)
B36: ミカフェート | D36: 23760 | H36: 50220 | I36: =SUM(C36:H36)
A37: 末 | B37: 浅野屋 仕入 | C37: 121163 | I37: =SUM(C37:H37)
B38: 美瑛 | C38: 17740 | I38: =SUM(C38:H38)
B39: ウエノヒロㇱ 仕入 | D39: 34873 | I39: =SUM(C39:H39)
B40: 浅野屋 | E40: 190051 | I40: =SUM(C40:H40)
B41: 食の道場 | G41: 21578 | I41: =SUM(C41:H41)
B43: ▶ 物販仕入れ | C43: =SUM(C44:C45) | D43: =SUM(D44:D45) | E43: =SUM(E44:E45) | F43: =SUM(F44:F45) | G43: =SUM(G44:G45) | H43: =SUM(H44:H45) | I43: =SUM(I44:I45)
B44: デジックス | D44: 22424 | F44: 18978 | I44: =SUM(C44:H44)
...

Sheet Eats_下期_1-6月
A1: ⑥ Eats 月間収支まとめ 下期_1-6月
A2: 日 | B2: 項目 | C2: R8.1月 | D2: R8.2月 | E2: R8.3月 | F2: R8.4月 | G2: R8.5月 | H2: R8.6月 | I2: 下期累計 | J2: 上期累計 | K2: 通期合計
A3: 【 支 出 】
B4: ▶ 給与・法定福利・福利 | C4: =SUM(C5:C7) | D4: =SUM(D5:D7) | E4: =SUM(E5:E7) | F4: =SUM(F5:F7) | G4: =SUM(G5:G7) | H4: =SUM(H5:H7) | I4: =SUM(I5:I7) | J4: =SUM(J5:J7) | K4: =SUM(K5:K7)
A5: 15 | B5: 業務委託費 | C5: 410417 | D5: 456513 | E5: 309931 | I5: =SUM(C5:H5) | J5: ='Eats_上期_7-12月'!I9 | K5: =I5+J5
A6: 末 | B6: 業務委託費 | C6: 1127270 | D6: 340629 | E6: 216179 | I6: =SUM(C6:H6) | J6: ='Eats_上期_7-12月'!I10 | K6: =I6+J6
B8: ▶ 光熱費 | C8: =SUM(C9:C13) | D8: =SUM(D9:D13) | E8: =SUM(E9:E13) | F8: =SUM(F9:F13) | G8: =SUM(G9:G13) | H8: =SUM(H9:H13) | I8: =SUM(I9:I13) | J8: =SUM(J9:J13) | K8: =SUM(K9:K13)
B9: 電気 | C9: 129698 | D9: 121158 | E9: 110510 | I9: =SUM(C9:H9) | J9: ='Eats_上期_7-12月'!I15 | K9: =I9+J9
B10: ガス 空調 | C10: 33396 | D10: 51916 | E10: 74027 | I10: =SUM(C10:H10) | J10: ='Eats_上期_7-12月'!I16 | K10: =I10+J10
B11: ガス 厨房 | C11: 19534 | D11: 21437 | E11: 22780 | I11: =SUM(C11:H11) | J11: ='Eats_上期_7-12月'!I17 | K11: =I11+J11
B12: 水道 | C12: 18301 | I12: =SUM(C12:H12) | J12: ='Eats_上期_7-12月'!I18 | K12: =I12+J12
B14: ▶ 銀行返済 | C14: =SUM(C15:C17) | D14: =SUM(D15:D17) | E14: =SUM(E15:E17) | F14: =SUM(F15:F17) | G14: =SUM(G15:G17) | H14: =SUM(H15:H17) | I14: =SUM(I15:I17) | J14: =SUM(J15:J17) | K14: =SUM(K15:K17)
A15: 25 | B15: 岐信 4000万 R7.7～（7回〜9回） | C15: 415473 | D15: 410771 | E15: 414591 | I15: =SUM(C15:H15) | J15: ='Eats_上期_7-12月'!I23 | K15: =I15+J15
B16: 3000万 商工中金 | C16: 511642 | D16: 509700 | E16: 512374 | I16: =SUM(C16:H16) | J16: ='Eats_上期_7-12月'!I21 | K16: =I16+J16
B18: ▶ 食材仕入れ | C18: =SUM(C19:C28) | D18: =SUM(D19:D28) | E18: =SUM(E19:E28) | F18: =SUM(F19:F28) | G18: =SUM(G19:G28) | H18: =SUM(H19:H28) | I18: =SUM(I19:I28) | J18: =SUM(J19:J28) | K18: =SUM(K19:K28)
A19: 末 | B19: 浅野 純也 仕入 | C19: 20658 | D19: 24325 | E19: 22952 | I19: =SUM(C19:H19) | J19: ='Eats_上期_7-12月'!I34 | K19: =I19+J19
B20: 大光 | C20: 39506 | D20: 25579 | E20: 22998 | I20: =SUM(C20:H20) | J20: ='Eats_上期_7-12月'!I26 | K20: =I20+J20
B21: 奥田庄司 商店 | C21: 20790 | D21: 41580 | E21: 20790 | I21: =SUM(C21:H21) | J21: ='Eats_上期_7-12月'!I31 | K21: =I21+J21
B22: 高瀬物産 仕入 | C22: 74429 | D22: 47862 | E22: 52219 | I22: =SUM(C22:H22) | J22: ='Eats_上期_7-12月'!I27 | K22: =I22+J22
B23: 名古屋製酪 仕入 | C23: 42099 | D23: 35705 | E23: 35292 | I23: =SUM(C23:H23) | J23: ='Eats_上期_7-12月'!I28 | K23: =I23+J23
B24: マルト水谷 仕入 | C24: 255491 | D24: 224262 | E24: 198161 | I24: =SUM(C24:H24) | J24: ='Eats_上期_7-12月'!I29 | K24: =I24+J24
B25: 丸福商店 仕入 | C25: 15914 | D25: 9192 | E25: 9410 | I25: =SUM(C25:H25) | J25: ='Eats_上期_7-12月'!I30 | K25: =I25+J25
A26: 2 | B26: 小口 店舗 | C26: 250000 | D26: 250000 | E26: 250000 | I26: =SUM(C26:H26) | J26: ='Eats_上期_7-12月'!I32 | K26: =I26+J26
B27: ミカフェート | E27: 26760 | I27: =SUM(C27:H27) | J27: ='Eats_上期_7-12月'!I36 | K27: =I27+J27
B29: ▶ 通信費 | C29: =SUM(C30:C32) | D29: =SUM(D30:D32) | E29: =SUM(E30:E32) | F29: =SUM(F30:F32) | G29: =SUM(G30:G32) | H29: =SUM(H30:H32) | I29: =SUM(I30:I32) | J29: =SUM(J30:J32) | K29: =SUM(K30:K32)
B30: 携帯 | C30: 2400 | D30: 2400 | E30: 2400 | I30: =SUM(C30:H30) | J30: ='Eats_上期_7-12月'!I47 | K30: =I30+J30
B31: 施設利用 通信警備入金機音響サーバー | C31: 69276 | D31: 69276 | E31: 69276 | I31: =SUM(C31:H31) | J31: ='Eats_上期_7-12月'!I48 | K31: =I31+J31
B33: ▶ 雑費 消耗品 修繕費 その他 | C33: =SUM(C34:C39) | D33: =SUM(D34:D39) | E33: =SUM(E34:E39) | F33: =SUM(F34:F39) | G33: =SUM(G34:G39) | H33: =SUM(H34:H39) | I33: =SUM(I34:I39) | J33: =SUM(J34:J39) | K33: =SUM(K34:K39)
B34: イーコム ゴミ回収 | C34: 31108 | D34: 30624 | E34: 30140 | I34: =SUM(C34:H34) | J34: ='Eats_上期_7-12月'!I51 | K34: =I34+J34
B35: マルト水谷 | C35: 8472 | D35: 13320 | E35: 13142 | I35: =SUM(C35:H35) | J35: ='Eats_上期_7-12月'!I56 | K35: =I35+J35
B36: ダスキン未来 | C36: 4884 | D36: 4884 | E36: 4884 | I36: =SUM(C36:H36) | J36: ='Eats_上期_7-12月'!I53 | K36: =I36+J36
B37: パスタボイラー | C37: 6900 | D37: 6900 | E37: 6900 | I37: =SUM(C37:H37) | K37: =I37+J37
B38: グローバル 粉雪アイスメーカー40回 | C38: 55000 | D38: 55000 | E38: 55000 | I38: =SUM(C38:H38) | J38: ='Eats_上期_7-12月'!I55 | K38: =I38+J38
B40: ▶ 広告宣伝費 | C40: =SUM(C41:C42) | D40: =SUM(D41:D42) | E40: =SUM(E41:E42) | F40: =SUM(F41:F42) | G40: =SUM(G41:G42) | H40: =SUM(H41:H42) | I40: =SUM(I41:I42) | J40: =SUM(J41:J42) | K40: =SUM(K41:K42)
B41: USEN デジタルサイネージ | C41: 32318 | D41: 32318 | E41: 32318 | I41: =SUM(C41:H41) | J41: ='Eats_上期_7-12月'!I64 | K41: =I41+J41
B43: ① 支出合計 | C43: =C4+C8+C14+C18+C29+C33+C40 | D43: =D4+D8+D14+D18+D29+D33+D40 | E43: =E4+E8+E14+E18+E29+E33+E40 | F43: =F4+F8+F14+F18+F29+F33+F40 | G43: =G4+G8+G14+G18+G29+G33+G40 | H43: =H4+H8+H14+H18+H29+H33+H40 | I43: =I4+I8+I14+I18+I29+I33+I40 | J43: =J4+J8+J14+J18+J29+J33+J40 | K43: =K4+K8+K14+K18+K29+K33+K40
A45: 【 ② 収 入（売上・粗利・雑収入など） 】
B46: ▶ 収入・支出項目 | C46: =SUM(C47:C56) | D46: =SUM(D47:D56) | E46: =SUM(E47:E56) | F46: =SUM(F47:F56) | G46: =SUM(G47:G56) | H46: =SUM(H47:H56) | I46: =SUM(I47:I56) | J46: =SUM(J47:J56) | K46: =SUM(K47:K56)
A47: 1週目 | B47: 売上入金 | C47: 360841 | D47: 227493 | E47: 116319 | I47: =SUM(C47:H47) | J47: ='Eats_上期_7-12月'!I71 | K47: =I47+J47
A48: 2週目 | B48: 売上入金 | C48: 120880 | D48: 192111 | E48: 113968 | I48: =SUM(C48:H48) | J48: ='Eats_上期_7-12月'!I72 | K48: =I48+J48
...

Sheet サイクルEV_上期_7-12月
A1: ⑦ サイクルEV 月間収支まとめ 上期_7-12月
A2: 日 | B2: 項目 | C2: R7.7月 | D2: R7.8月 | E2: R7.9月 | F2: R7.10月 | G2: R7.11月 | H2: R7.12月 | I2: 累 計
A3: 【 支 出 】
B4: ▶ 給与・法定福利・福利 | C4: =SUM(C5:C10) | D4: =SUM(D5:D10) | E4: =SUM(E5:E10) | F4: =SUM(F5:F10) | G4: =SUM(G5:G10) | H4: =SUM(H5:H10) | I4: =SUM(I5:I10)
A5: 20 | B5: 給与支給 社員 （成田AJで支払） | C5: 421119 | D5: 431973 | E5: 421747 | F5: 421119 | G5: 431659 | H5: 421747 | I5: =SUM(C5:H5)
A6: 20 | B6: 給与支給 PA | C6: 186409 | D6: 231279 | E6: 223704 | F6: 174660 | G6: 248283 | H6: 195052 | I6: =SUM(C6:H6)
A7: 20 | B7: 社会保険 社員 会社負担 | C7: 63446 | D7: 63506 | E7: 63450 | F7: 63446 | G7: 63504 | H7: 63450 | I7: =SUM(C7:H7)
A8: 20 | B8: 社会保険 PA 会社負担 | C8: 29353 | D8: 29600 | E8: 29558 | F8: 30781 | G8: 31186 | H8: 30893 | I8: =SUM(C8:H8)
A9: 末 | B9: 杉山氏 交通費（1/3） | C9: 33158 | F9: 79580 | H9: 107252 | I9: =SUM(C9:H9)
B11: ▶ 光熱費 | C11: =SUM(C12:C16) | D11: =SUM(D12:D16) | E11: =SUM(E12:E16) | F11: =SUM(F12:F16) | G11: =SUM(G12:G16) | H11: =SUM(H12:H16) | I11: =SUM(I12:I16)
B12: 電気 | C12: 22327 | D12: 24787 | E12: 24485 | F12: 19278 | G12: 20001 | H12: 18941 | I12: =SUM(C12:H12)
B13: ガス 空調 | C13: 5575 | D13: 38490 | E13: 67470 | F13: 62438 | G13: 27335 | H13: 3964 | I13: =SUM(C13:H13)
B14: ガス 給湯 | C14: 171 | D14: 67 | E14: 99 | F14: 97 | H14: 285 | I14: =SUM(C14:H14)
B15: 水道 | E15: 3366 | F15: 3366 | G15: 3366 | I15: =SUM(C15:H15)
B17: ▶ 銀行返済 | C17: =SUM(C18:C21) | D17: =SUM(D18:D21) | E17: =SUM(E18:E21) | F17: =SUM(F18:F21) | G17: =SUM(G18:G21) | H17: =SUM(H18:H21) | I17: =SUM(I18:I21)
A18: 20 | B18: BLOCK47 大共6000万 | C18: 330000 | D18: 330000 | E18: 330000 | F18: 330000 | G18: 330000 | H18: 330000 | I18: =SUM(C18:H18)
B19: BLOCK47 十六6000万 | C19: 330000 | D19: 330000 | E19: 330000 | F19: 330000 | G19: 330000 | H19: 330000 | I19: =SUM(C19:H19)
B20: 商工中金5千万R17.9迄（61回〜63回） | F20: 313551 | G20: 312192 | H20: 312980 | I20: =SUM(C20:H20)
B22: ▶ サイクル仕入れ | C22: =SUM(C23:C37) | D22: =SUM(D23:D37) | E22: =SUM(E23:E37) | F22: =SUM(F23:F37) | G22: =SUM(G23:G37) | H22: =SUM(H23:H37) | I22: =SUM(I23:I37)
A23: 20 | B23: フカヤ 仕入れ | C23: 33292 | D23: 54401 | E23: 39816 | F23: 44106 | G23: 22177 | H23: 63386 | I23: =SUM(C23:H23)
A24: 31 | B24: なるおか 24回R9.2月迄十六リース | C24: 70070 | D24: 70070 | E24: 70070 | F24: 70070 | G24: 70070 | H24: 70070 | I24: =SUM(C24:H24)
B25: なるおかサイクル | C25: 114700 | E25: 21028 | I25: =SUM(C25:H25)
B26: みずほ東芝リース | C26: 9350 | D26: 9350 | E26: 9350 | F26: 9350 | G26: 9350 | H26: 9350 | I26: =SUM(C26:H26)
B27: JOYカート 24回R9.4月迄十六リース | C27: 24400 | D27: 24400 | E27: 24400 | F27: 24400 | G27: 24400 | H27: 24400 | I27: =SUM(C27:H27)
A28: 10 | B28: ダイヤテック 仕入れ | C28: 16980 | G28: 19928 | H28: 11528 | I28: =SUM(C28:H28)
B29: フタバ商店 仕入れ | C29: 49975 | F29: 25132 | G29: 14647 | I29: =SUM(C29:H29)
B30: スワロー | D30: 271960 | G30: 152230 | H30: 12620 | I30: =SUM(C30:H30)
B31: スワロー | G31: 145280 | I31: =SUM(C31:H31)
B32: 日本イベント企画 | E32: 102500 | G32: 32500 | I32: =SUM(C32:H32)
B33: アベントゥライフ | G33: 29000 | H33: 14500 | I33: =SUM(C33:H33)
B34: サギサカ | C34: 95370 | I34: =SUM(C34:H34)
B35: ウィズ | C35: 788260 | I35: =SUM(C35:H35)
B36: ウィズ ドギーバイク | E36: 400400 | I36: =SUM(C36:H36)
B38: ▶ 通信費 | C38: =SUM(C39:C41) | D38: =SUM(D39:D41) | E38: =SUM(E39:E41) | F38: =SUM(F39:F41) | G38: =SUM(G39:G41) | H38: =SUM(H39:H41) | I38: =SUM(I39:I41)
B39: 携帯 | C39: 4800 | D39: 4800 | E39: 4800 | F39: 4800 | G39: 4800 | H39: 4800 | I39: =SUM(C39:H39)
B40: 施設利用 通信警備入金機音響サーバー | C40: 34638 | D40: 34638 | E40: 34638 | F40: 34638 | G40: 34638 | H40: 34638 | I40: =SUM(C40:H40)
B42: ▶ 雑費 消耗品 修繕費 その他 | C42: =SUM(C43:C48) | D42: =SUM(D43:D48) | E42: =SUM(E43:E48) | F42: =SUM(F43:F48) | G42: =SUM(G43:G48) | H42: =SUM(H43:H48) | I42: =SUM(I43:I48)
B43: イーコム ゴミ回収 | C43: 11242 | D43: 11726 | E43: 11363 | F43: 31284 | G43: 11726 | H43: 11242 | I43: =SUM(C43:H43)
A44: 8 | B44: 小口 | D44: 50000 | E44: 50000 | F44: 50000 | I44: =SUM(C44:H44)
A45: 22 | B45: 小口 | F45: 120000 | I45: =SUM(C45:H45)
...

Sheet サイクルEV_下期_1-6月
A1: ⑦ サイクルEV 月間収支まとめ 下期_1-6月
A2: 日 | B2: 項目 | C2: R8.1月 | D2: R8.2月 | E2: R8.3月 | F2: R8.4月 | G2: R8.5月 | H2: R8.6月 | I2: 下期累計 | J2: 上期累計 | K2: 通期合計
A3: 【 支 出 】
B4: ▶ 給与・法定福利・福利 | C4: =SUM(C5:C9) | D4: =SUM(D5:D9) | E4: =SUM(E5:E9) | F4: =SUM(F5:F9) | G4: =SUM(G5:G9) | H4: =SUM(H5:H9) | I4: =SUM(I5:I9) | J4: =SUM(J5:J9) | K4: =SUM(K5:K9)
A5: 20 | B5: 給与支給 社員 （成田AJで支払） | C5: 421433 | D5: 421433 | E5: 420805 | I5: =SUM(C5:H5) | J5: ='サイクルEV_上期_7-12月'!I5 | K5: =I5+J5
A6: 20 | B6: 給与支給 PA | C6: 141550 | D6: 130686 | E6: 122065 | I6: =SUM(C6:H6) | J6: ='サイクルEV_上期_7-12月'!I6 | K6: =I6+J6
A7: 20 | B7: 社会保険 社員 会社負担 | C7: 63448 | D7: 63448 | E7: 63444 | I7: =SUM(C7:H7) | J7: ='サイクルEV_上期_7-12月'!I7 | K7: =I7+J7
A8: 20 | B8: 社会保険 PA 会社負担 | C8: 30599 | D8: 30539 | E8: 30491 | I8: =SUM(C8:H8) | J8: ='サイクルEV_上期_7-12月'!I8 | K8: =I8+J8
B10: ▶ 光熱費 | C10: =SUM(C11:C15) | D10: =SUM(D11:D15) | E10: =SUM(E11:E15) | F10: =SUM(F11:F15) | G10: =SUM(G11:G15) | H10: =SUM(H11:H15) | I10: =SUM(I11:I15) | J10: =SUM(J11:J15) | K10: =SUM(K11:K15)
B11: 電気 | C11: 18942 | D11: 17831 | E11: 16361 | I11: =SUM(C11:H11) | J11: ='サイクルEV_上期_7-12月'!I12 | K11: =I11+J11
B12: ガス 空調 | C12: 11966 | D12: 28884 | E12: 34370 | I12: =SUM(C12:H12) | J12: ='サイクルEV_上期_7-12月'!I13 | K12: =I12+J12
B13: ガス 給湯 | C13: 318 | D13: 328 | E13: 736 | I13: =SUM(C13:H13) | J13: ='サイクルEV_上期_7-12月'!I14 | K13: =I13+J13
B14: 水道 | C14: 3366 | I14: =SUM(C14:H14) | J14: ='サイクルEV_上期_7-12月'!I15 | K14: =I14+J14
B16: ▶ 銀行返済 | C16: =SUM(C17:C20) | D16: =SUM(D17:D20) | E16: =SUM(E17:E20) | F16: =SUM(F17:F20) | G16: =SUM(G17:G20) | H16: =SUM(H17:H20) | I16: =SUM(I17:I20) | J16: =SUM(J17:J20) | K16: =SUM(K17:K20)
A17: 20 | B17: BLOCK47 大共6000万 | C17: 330000 | D17: 330000 | E17: 330000 | I17: =SUM(C17:H17) | J17: ='サイクルEV_上期_7-12月'!I18 | K17: =I17+J17
B18: BLOCK47 十六6000万 | C18: 330000 | D18: 330000 | E18: 330000 | I18: =SUM(C18:H18) | J18: ='サイクルEV_上期_7-12月'!I19 | K18: =I18+J18
B19: 商工中金5千万R17.9迄（64回〜66回） | C19: 312695 | D19: 309273 | E19: 312124 | I19: =SUM(C19:H19) | J19: ='サイクルEV_上期_7-12月'!I20 | K19: =I19+J19
B21: ▶ サイクル仕入れ | C21: =SUM(C22:C28) | D21: =SUM(D22:D28) | E21: =SUM(E22:E28) | F21: =SUM(F22:F28) | G21: =SUM(G22:G28) | H21: =SUM(H22:H28) | I21: =SUM(I22:I28) | J21: =SUM(J22:J28) | K21: =SUM(K22:K28)
B22: みずほ東芝リース | C22: 9350 | D22: 9350 | E22: 9350 | I22: =SUM(C22:H22) | J22: ='サイクルEV_上期_7-12月'!I26 | K22: =I22+J22
A23: 31 | B23: なるおか 24回R9.2月迄十六リース | C23: 70070 | D23: 70070 | E23: 70070 | I23: =SUM(C23:H23) | J23: ='サイクルEV_上期_7-12月'!I24 | K23: =I23+J23
B24: JOYカート 24回R9.4月迄十六リース | C24: 24400 | D24: 24400 | E24: 24400 | I24: =SUM(C24:H24) | J24: ='サイクルEV_上期_7-12月'!I27 | K24: =I24+J24
