Workbook

Sheet 設定
A1: 週間資金繰表 設定
A3: ■ 対象年月
A4: 西 暦（年） | B4: 2026 | C4: ← 4桁で入力
A5: 月 | B5: 4 | C5: ← 1〜12で入力
A7: ■ 前月末残高
A8: AMUSE 前月末残 | B8: 2186099 | C8: ← 金額を入力（円）
A9: 大日産業 前月末残 | B9: 5083029 | C9: ← 金額を入力（円）
A11: ※ 年・月・前月末残を変更すると、資金繰表の日付・残高が自動で更新されます。

Sheet 祝日
A1: 祝日一覧（2025-2027）
A2: 45658
A3: 45670
A4: 45699
A5: 45711
A6: 45712
A7: 45736
A8: 45776
A9: 45780
A10: 45781
A11: 45782
A12: 45783
A13: 45859
... A53: 46714

Sheet AMUSE
A1: =" 週間資金繰表 令和"&(設定!B2-2018)&"年"&設定!B3&"月 AMUSE（岐信当座）"
A2: 前 月 末 残 | D2: =設定!$B$8 | E2: ← 設定シートで変更できます
D3: =IFERROR(WORKDAY(DATE(設定!$B$2,設定!$B$3,1)-1,1,祝日!$A:$A),"") | E3: =IF(D3="","",IF(D3>=EOMONTH(D3,0),"",IFERROR(WORKDAY(D3,1,祝日!$A:$A),""))) | F3: =IF(E3="","",IF(E3>=EOMONTH(D3,0),"",IFERROR(WORKDAY(E3,1,祝日!$A:$A),""))) | G3: =IF(F3="","",IF(F3>=EOMONTH(D3,0),"",IFERROR(WORKDAY(F3,1,祝日!$A:$A),""))) | H3: =IF(G3="","",IF(G3>=EOMONTH(D3,0),"",IFERROR(WORKDAY(G3,1,祝日!$A:$A),""))) | I3: =IF(H3="","",IF(H3>=EOMONTH(D3,0),"",IFERROR(WORKDAY(H3,1,祝日!$A:$A),""))) | J3: =IF(I3="","",IF(I3>=EOMONTH(D3,0),"",IFERROR(WORKDAY(I3,1,祝日!$A:$A),""))) | K3: =IF(J3="","",IF(J3>=EOMONTH(D3,0),"",IFERROR(WORKDAY(J3,1,祝日!$A:$A),""))) | L3: =IF(K3="","",IF(K3>=EOMONTH(D3,0),"",IFERROR(WORKDAY(K3,1,祝日!$A:$A),""))) | M3: =IF(L3="","",IF(L3>=EOMONTH(D3,0),"",IFERROR(WORKDAY(L3,1,祝日!$A:$A),""))) | N3: =IF(M3="","",IF(M3>=EOMONTH(D3,0),"",IFERROR(WORKDAY(M3,1,祝日!$A:$A),""))) | O3: =IF(N3="","",IF(N3>=EOMONTH(D3,0),"",IFERROR(WORKDAY(N3,1,祝日!$A:$A),""))) | P3: =IF(O3="","",IF(O3>=EOMONTH(D3,0),"",IFERROR(WORKDAY(O3,1,祝日!$A:$A),""))) | Q3: =IF(P3="","",IF(P3>=EOMONTH(D3,0),"",IFERROR(WORKDAY(P3,1,祝日!$A:$A),""))) | R3: =IF(Q3="","",IF(Q3>=EOMONTH(D3,0),"",IFERROR(WORKDAY(Q3,1,祝日!$A:$A),""))) | S3: =IF(R3="","",IF(R3>=EOMONTH(D3,0),"",IFERROR(WORKDAY(R3,1,祝日!$A:$A),""))) | T3: =IF(S3="","",IF(S3>=EOMONTH(D3,0),"",IFERROR(WORKDAY(S3,1,祝日!$A:$A),""))) | U3: =IF(T3="","",IF(T3>=EOMONTH(D3,0),"",IFERROR(WORKDAY(T3,1,祝日!$A:$A),""))) | V3: =IF(U3="","",IF(U3>=EOMONTH(D3,0),"",IFERROR(WORKDAY(U3,1,祝日!$A:$A),""))) | W3: =IF(V3="","",IF(V3>=EOMONTH(D3,0),"",IFERROR(WORKDAY(V3,1,祝日!$A:$A),""))) | X3: =IF(W3="","",IF(W3>=EOMONTH(D3,0),"",IFERROR(WORKDAY(W3,1,祝日!$A:$A),""))) | Y3: =IF(X3="","",IF(X3>=EOMONTH(D3,0),"",IFERROR(WORKDAY(X3,1,祝日!$A:$A),""))) | Z3: =IF(Y3="","",IF(Y3>=EOMONTH(D3,0),"",IFERROR(WORKDAY(Y3,1,祝日!$A:$A),""))) | AA3: =IF(WORKDAY(EOMONTH(D3,0)-1,1,祝日!$A:$A)=EOMONTH(D3,0),"",WORKDAY(EOMONTH(D3,0),1,祝日!$A:$A))
A4: 引落日等 | B4: 支 払 項 目 | D4: =IF(D3="","",TEXT(D3,"m/d(aaa)")) | E4: =IF(E3="","",TEXT(E3,"m/d(aaa)")) | F4: =IF(F3="","",TEXT(F3,"m/d(aaa)")) | G4: =IF(G3="","",TEXT(G3,"m/d(aaa)")) | H4: =IF(H3="","",TEXT(H3,"m/d(aaa)")) | I4: =IF(I3="","",TEXT(I3,"m/d(aaa)")) | J4: =IF(J3="","",TEXT(J3,"m/d(aaa)")) | K4: =IF(K3="","",TEXT(K3,"m/d(aaa)")) | ... AA4: =IF(AA3="","",TEXT(AA3,"m/d(aaa)")) | AB4: 月 計
A5: 【 支 出 】
A6: 10日 | B6: NTT | K6: 21004 | V6: 15950 | X6: 6318 | AB6: =SUM(D6:AA6)
A7: TCリース | B7: NTT（TCリース） | X7: 5291 | AB7: =SUM(D7:AA7)
B8: 大日IP定額 | AB8: =SUM(D8:AA8)
B9: KDDI | W9: 2700 | AB9: =SUM(D9:AA9)
B10: 大日へ | J10: 440000 | X10: 5000000 | AB10: =SUM(D10:AA10)
B11: テレマーカー | AB11: =SUM(D11:AA11)
B12: 山田組 | Q12: 19360 | AB12: =SUM(D12:AA12)
B13: ブリックス社労士 | M13: 30935 | AB13: =SUM(D13:AA13)
B14: ぎしんBIZ | M14: 3300 | AB14: =SUM(D14:AA14)
B15: 東邦ガス | AB15: =SUM(D15:AA15)
B16: 水道料 | AB16: =SUM(D16:AA16)
B17: 電気料 | N17: 862474 | AB17: =SUM(D17:AA17)
B18: 十六リース（設備） | J18: 288200 | AB18: =SUM(D18:AA18)
B19: 十六リース（機械） | J19: 2718595 | AB19: =SUM(D19:AA19)
A20: ロボットペイ | B20: イージス | M20: 11165 | AB20: =SUM(D20:AA20)
B21: 高田繊維 | J21: 432400 | P21: 142316 | AB21: =SUM(D21:AA21)
B22: しんきんコピー機 | U22: 13860 | AB22: =SUM(D22:AA22)
B23: 位田会計 | U23: 127600 | AB23: =SUM(D23:AA23)
B24: 源泉 | AB24: =SUM(D24:AA24)
B25: 住民税 | M25: 61500 | AB25: =SUM(D25:AA25)
B26: 県遊協 | AB26: =SUM(D26:AA26)
B27: 労働保険 | AB27: =SUM(D27:AA27)
B28: でんさい手数料 | P28: 15840 | AB28: =SUM(D28:AA28)
B29: 振込手数料 | K29: 34760 | AB29: =SUM(D29:AA29)
B30: 給料 | P30: 2758340 | AB30: =SUM(D30:AA30)
B31: 役員/株主返済 | AB31: =SUM(D31:AA31)
B32: 社会保険料 | X32: 640000 | AB32: =SUM(D32:AA32)
B33: 固定資産税 | AB33: =SUM(D33:AA33)
B34: グローリー | V34: 360640 | AB34: =SUM(D34:AA34)
B35: フジコム手形 | Q35: 1557215 | AB35: =SUM(D35:AA35)
A36: 26日 | B36: 北出家賃 | W36: 76250 | AB36: =SUM(D36:AA36)
A37: 26日 | B37: アルソック入金機 | W37: 88000 | AB37: =SUM(D37:AA37)
B38: 銀行返済 | W38: 3700000 | AB38: =SUM(D38:AA38)
A39: 26日 | B39: ヤマト26日 | V39: 660 | AB39: =SUM(D39:AA39)
A40: 27日 | B40: 北電子 | V40: 49280 | AB40: =SUM(D40:AA40)
...

Sheet 大日産業
A1: =" 週間資金繰表 令和"&(設定!B2-2018)&"年"&設定!B3&"月 大日産業（岐信当座）"
A2: 前 月 末 残 | D2: =設定!$B$9 | E2: ← 設定シートで変更できます
D3: =IFERROR(WORKDAY(DATE(設定!$B$2,設定!$B$3,1)-1,1,祝日!$A:$A),"") | E3: =IF(D3="","",IF(D3>=EOMONTH(D3,0),"",IFERROR(WORKDAY(D3,1,祝日!$A:$A),""))) | F3: =IF(E3="","",IF(E3>=EOMONTH(D3,0),"",IFERROR(WORKDAY(E3,1,祝日!$A:$A),""))) | G3: =IF(F3="","",IF(F3>=EOMONTH(D3,0),"",IFERROR(WORKDAY(F3,1,祝日!$A:$A),""))) | H3: =IF(G3="","",IF(G3>=EOMONTH(D3,0),"",IFERROR(WORKDAY(G3,1,祝日!$A:$A),""))) | I3: =IF(H3="","",IF(H3>=EOMONTH(D3,0),"",IFERROR(WORKDAY(H3,1,祝日!$A:$A),""))) | J3: =IF(I3="","",IF(I3>=EOMONTH(D3,0),"",IFERROR(WORKDAY(I3,1,祝日!$A:$A),""))) | K3: =IF(J3="","",IF(J3>=EOMONTH(D3,0),"",IFERROR(WORKDAY(J3,1,祝日!$A:$A),""))) | L3: =IF(K3="","",IF(K3>=EOMONTH(D3,0),"",IFERROR(WORKDAY(K3,1,祝日!$A:$A),""))) | M3: =IF(L3="","",IF(L3>=EOMONTH(D3,0),"",IFERROR(WORKDAY(L3,1,祝日!$A:$A),""))) | N3: =IF(M3="","",IF(M3>=EOMONTH(D3,0),"",IFERROR(WORKDAY(M3,1,祝日!$A:$A),""))) | O3: =IF(N3="","",IF(N3>=EOMONTH(D3,0),"",IFERROR(WORKDAY(N3,1,祝日!$A:$A),""))) | P3: =IF(O3="","",IF(O3>=EOMONTH(D3,0),"",IFERROR(WORKDAY(O3,1,祝日!$A:$A),""))) | Q3: =IF(P3="","",IF(P3>=EOMONTH(D3,0),"",IFERROR(WORKDAY(P3,1,祝日!$A:$A),""))) | R3: =IF(Q3="","",IF(Q3>=EOMONTH(D3,0),"",IFERROR(WORKDAY(Q3,1,祝日!$A:$A),""))) | S3: =IF(R3="","",IF(R3>=EOMONTH(D3,0),"",IFERROR(WORKDAY(R3,1,祝日!$A:$A),""))) | T3: =IF(S3="","",IF(S3>=EOMONTH(D3,0),"",IFERROR(WORKDAY(S3,1,祝日!$A:$A),""))) | U3: =IF(T3="","",IF(T3>=EOMONTH(D3,0),"",IFERROR(WORKDAY(T3,1,祝日!$A:$A),""))) | V3: =IF(U3="","",IF(U3>=EOMONTH(D3,0),"",IFERROR(WORKDAY(U3,1,祝日!$A:$A),""))) | W3: =IF(V3="","",IF(V3>=EOMONTH(D3,0),"",IFERROR(WORKDAY(V3,1,祝日!$A:$A),""))) | X3: =IF(W3="","",IF(W3>=EOMONTH(D3,0),"",IFERROR(WORKDAY(W3,1,祝日!$A:$A),""))) | Y3: =IF(X3="","",IF(X3>=EOMONTH(D3,0),"",IFERROR(WORKDAY(X3,1,祝日!$A:$A),""))) | Z3: =IF(Y3="","",IF(Y3>=EOMONTH(D3,0),"",IFERROR(WORKDAY(Y3,1,祝日!$A:$A),""))) | AA3: =IF(WORKDAY(EOMONTH(D3,0)-1,1,祝日!$A:$A)=EOMONTH(D3,0),"",WORKDAY(EOMONTH(D3,0),1,祝日!$A:$A))
A4: 引落日等 | B4: 支 払 項 目 | D4: =IF(D3="","",TEXT(D3,"m/d(aaa)")) | E4: =IF(E3="","",TEXT(E3,"m/d(aaa)")) | F4: =IF(F3="","",TEXT(F3,"m/d(aaa)")) | G4: =IF(G3="","",TEXT(G3,"m/d(aaa)")) | H4: =IF(H3="","",TEXT(H3,"m/d(aaa)")) | I4: =IF(I3="","",TEXT(I3,"m/d(aaa)")) | J4: =IF(J3="","",TEXT(J3,"m/d(aaa)")) | K4: =IF(K3="","",TEXT(K3,"m/d(aaa)")) | ... AA4: =IF(AA3="","",TEXT(AA3,"m/d(aaa)")) | AB4: 月 計
A5: 【 支 出 】
A6: トヨタF | B6: ENEOS ビジネス | G6: 74805 | AB6: =SUM(D6:AA6)
B7: JCB | K7: 82270 | AB7: =SUM(D7:AA7)
B8: JCB（ガソリン） | AB8: =SUM(D8:AA8)
B9: タキ新聞店 | G9: 3350 | AB9: =SUM(D9:AA9)
B10: セディナ三井住友 | G10: 5562 | K10: 1470 | AB10: =SUM(D10:AA10)
B11: 安心財団 | G11: 2000 | AB11: =SUM(D11:AA11)
B12: トヨタ | AB12: =SUM(D12:AA12)
B13: KDDI | X13: 2500 | AB13: =SUM(D13:AA13)
B14: NTT | X14: 14532 | AB14: =SUM(D14:AA14)
B15: しょうしんへ | AB15: =SUM(D15:AA15)
A16: 22日 | B16: しんきんリース | S16: 652052 | AB16: =SUM(D16:AA16)
B17: 十六カード | J17: 610992 | AB17: =SUM(D17:AA17)
B18: 十六リース | AB18: =SUM(D18:AA18)
A19: 20日 | B19: 商工中金へ | Q19: 850000 | AB19: =SUM(D19:AA19)
B20: 証書借入 | V20: 530000 | AB20: =SUM(D20:AA20)
B21: ウェルピア羽島 | J21: 1650000 | AB21: =SUM(D21:AA21)
B22: ウェルピアへ | AB22: =SUM(D22:AA22)
B23: AMUSEへ | AB23: =SUM(D23:AA23)
B24: ブリックス社労士 | M24: 22952 | AB24: =SUM(D24:AA24)
B25: 東邦液化ガス | AB25: =SUM(D25:AA25)
B26: 水道 | AB26: =SUM(D26:AA26)
B27: 電気料 | AB27: =SUM(D27:AA27)
B28: 源泉 | K28: 6650 | AB28: =SUM(D28:AA28)
B29: 住民税 | M29: 25800 | AB29: =SUM(D29:AA29)
B30: 労働保険料 | AB30: =SUM(D30:AA30)
B31: 振込手数料 | K31: 32285 | AB31: =SUM(D31:AA31)
B32: 小口 | Q32: 500000 | AB32: =SUM(D32:AA32)
B33: 給料 | P33: 1239784 | AB33: =SUM(D33:AA33)
B34: ボディケア費用 | AB34: =SUM(D34:AA34)
B35: サイクル費用 | J35: 19249 | P35: 47420 | AB35: =SUM(D35:AA35)
B36: ボディケア30日 | W36: 351150 | AB36: =SUM(D36:AA36)
B37: サイクル月末 | W37: 100592 | AB37: =SUM(D37:AA37)
B38: Eats月末 | AB38: =SUM(D38:AA38)
A39: 26日 | B39: 本社月末振込 | W39: 70350 | AB39: =SUM(D39:AA39)
A40: 26日 | B40: GM地権者振＋他 | W40: 3216251 | AB40: =SUM(D40:AA40)
...
